Workbook
Name _Hlk13573816: субаренда!#REF!
Name Подразделения: [1]Списки!$A$26:$A$56

Sheet субаренда
B2: № ТТ | C2: адрес | D2: субарендатор | F2: ОКПО | G2: площадь, мкв | H2: Группа товара | I2: акт пп | J2: № договора | K2: Счетчик | L2: 45777 | M2: 45808 | N2: 45838 | O2: 45869 | P2: 45870 | Q2: 45901 | R2: 45931 | S2: 45962 | T2: 45992 | U2: 46023 | V2: Коэф. | W2: Потребление травень 2025 | X2: Потребление червень 2025 | Y2: Потребление липень 2025 | Z2: Потребления сентябрь 2025 | AA2: Потребления октбярь 2025 | AB2: Потребления ноябрь 2025 | AC2: Потребления декабрь 2025 | AD2: Потребления січень 2026 | AE2: Стоимость | AF2: Итого
A3: л | B3: 1-1 | C3: Житомирська обл., м. Житомир, проспект Миру, буд. 15 | D3: ТОВ "Подорожник Житомир" | E3: электроэнергия | F3: 41087452 | G3: 74.8 | H3: аптека | I3: 44795 | J3: № 17/07 від 19 серпня 2022 року | L3: 157082 | M3: 158047 | N3: 158695 | O3: 159785.6 | P3: 160610.5 | Q3: 161338 | R3: 162542 | S3: 163725 | T3: 165551 | U3: 168328 | V3: 1 | W3: =M3-L3 -> 965 | X3: =N3-M3 -> 648 | Y3: =P3-O3 -> 824.9 | Z3: =Q3-P3 -> 727.5 | AA3: =R3-Q3 -> 1204 | AB3: =S3-R3 -> 1183 | AC3: =T3-S3 -> 1826 | AD3: =U3-T3 -> 2777 | AE3: 14.60538 | AF3: =V3*AD3*AE3 -> 40559.14
A4: л | B4: 1-1 | C4: Житомирська обл., м. Житомир, проспект Миру, буд. 15 | E4: Вода | L4: 56 | M4: 58 | N4: 60 | O4: 62 | P4: 64 | Q4: 66 | R4: 68 | S4: 70 | T4: 71 | U4: 71 | V4: 1 | W4: =M4-L4 -> 2 | X4: =N4-M4 -> 2 | Y4: =P4-O4 -> 2 | Z4: =Q4-P4 -> 2 | AA4: =R4-Q4 -> 2 | AB4: =S4-R4 -> 2 | AC4: =T4-S4 -> 1 | AD4: =U4-T4 -> 0 | AE4: 83.177101 | AF4: =V4*AD4*AE4 -> 0
A5: л | B5: 2 | C5: м. Київ, вул. Володимирська, 73/77 | D5: ФОП Ільєнко О.М. | E5: Вода | F5: 2653404868 | G5: 1 | H5: водомат | I5: 45689 | J5: № СУБ-25/ІОМ-Л від 01 лютого 2025 року | L5: 1678.41 | M5: 1699.51 | N5: 1722.02 | O5: 1742.89 | P5: 1765.61 | Q5: 1787.07 | R5: 1811.24 | S5: 1840.66 | T5: 1863.28 | U5: 1885.23 | V5: 1 | W5: =M5-L5 -> 21.1 | X5: =N5-M5 -> 22.51 | Y5: =P5-O5 -> 22.72 | Z5: =Q5-P5 -> 21.46 | AA5: =R5-Q5 -> 24.17 | AB5: =S5-R5 -> 29.42 | AC5: =T5-S5 -> 22.62 | AD5: =U5-T5 -> 21.95 | AE5: 49.691667 | AF5: =V5*AD5*AE5 -> 1090.7321
A6: л | B6: 3 | C6: м. Київ, вул. Раїси Окіпної, будинок 3 | D6: ФОП Красій Я.М. | E6: электроэнергия | F6: 3092608596 | G6: 12 | H6: кофе-чай | I6: 45627 | J6: № СУБ-24/М-3/1 від 01 грудня 2024 року | L6: 713382 | M6: 713960.57 | N6: 714695 | O6: 715651.35 | P6: 716539.85 | Q6: 717295.41 | R6: 717609.95 | S6: 717974.67 | T6: 718481.49 | U6: 719102.6 | V6: 1 | W6: =M6-L6 -> 578.57 | X6: =N6-M6 -> 734.43 | Y6: =P6-O6 -> 888.5 | Z6: =Q6-P6 -> 755.56 | AA6: =R6-Q6 -> 314.54 | AB6: =S6-R6 -> 364.72 | AC6: =T6-S6 -> 506.82 | AD6: =U6-T6 -> 621.11 | AE6: 11.5641 | AF6: =V6*AD6*AE6 -> 7182.5782 | AH6: =1.2*9.92662 -> 11.911944
A7: л | B7: 3 | C7: м. Київ, вул. Раїси Окіпної, будинок 3 | E7: Вода | L7: 129.31 | M7: 130.55 | N7: 131.6 | O7: 132.67 | P7: 133.83 | Q7: 135.23 | R7: 136.11 | S7: 137.09 | T7: 138.24 | U7: 140.25 | V7: 1 | W7: =M7-L7 -> 1.24 | X7: =N7-M7 -> 1.05 | Y7: =P7-O7 -> 1.16 | Z7: =Q7-P7 -> 1.4 | AA7: =R7-Q7 -> 0.88 | AB7: =S7-R7 -> 0.98 | AC7: =T7-S7 -> 1.15 | AD7: =U7-T7 -> 2.01 | AE7: 53.478667 | AF7: =V7*AD7*AE7 -> 107.49212
A8: л | B8: 4-1 | C8: Київська обл., м. Ірпінь, смт. Коцюбинське, вул. Пономарьова, 28-а | D8: ФОП Ільєнко О.М. | E8: Вода | F8: 2653404868 | G8: 1 | H8: водомат | I8: 45717 | J8: № СУБ-25/ІОМ-Л від 01 лютого 2025 року | L8: 27.32 | M8: 38.88 | N8: 50.14 | O8: 63.91 | P8: 74.09 | Q8: 86.05 | R8: 99.13 | S8: 112.8 | T8: 128.1 | U8: 133.35 | V8: 1 | W8: =M8-L8 -> 11.56 | X8: =N8-M8 -> 11.26 | Y8: =P8-O8 -> 10.18 | Z8: =Q8-P8 -> 11.96 | AA8: =R8-Q8 -> 13.08 | AB8: =S8-R8 -> 13.67 | AC8: =T8-S8 -> 15.3 | AD8: =U8-T8 -> 5.25 | AE8: 59.287826 | AF8: =V8*AD8*AE8 -> 311.26109
A9: л | B9: 4-1 | C9: Київська обл., м. Ірпінь, смт. Коцюбинське, вул. Пономарьова, 28-а | D9: ФОП Морозова І.В. | E9: Вода | F9: 2679220364 | G9: 1 | H9: кавовий апарат | I9: 45359 | J9: № СУБ-24/М-4/1 від 08 березня 2024 року | V9: 1 | W9: =M9-L9 -> 0 | X9: =N9-M9 -> 0 | Y9: =P9-O9 -> 0 | Z9: =Q9-P9 -> 0 | AA9: =R9-Q9 -> 0 | AB9: =S9-R9 -> 0 | AC9: =T9-S9 -> 0 | AD9: =U9-T9 -> 0 | AE9: -
A10: л | B10: 5 | C10: м. Київ, вул. Якуба Колоса, № 2 (Літера А) | D10: ФОП Ільєнко О.М. | E10: Вода | F10: 2653404868 | G10: 1 | H10: водомат | I10: 45689 | J10: № СУБ-25/ІОМ-Л від 01 лютого 2025 року | L10: 2372 | M10: 2395 | N10: 2413 | O10: 2431 | P10: 2447.54 | Q10: 2464 | R10: 2476 | S10: 2488 | T10: 2503 | U10: 2517 | V10: 1 | W10: =M10-L10 -> 23 | X10: =N10-M10 -> 18 | Y10: =P10-O10 -> 16.54 | Z10: =Q10-P10 -> 16.46 | AA10: =R10-Q10 -> 12 | AB10: =S10-R10 -> 12 | AC10: =T10-S10 -> 15 | AD10: =U10-T10 -> 14 | AE10: 57.37543 | AF10: =V10*AD10*AE10 -> 803.25602
A11: л | B11: 5 | C11: м. Київ, вул. Якуба Колоса, № 2 (Літера А) | D11: ФОП Капійчук О.С. | E11: электроэнергия | F11: 3556512845 | G11: 1 | H11: кавовий апарат | I11: 45814 | J11: № СУБ-25/М-5/2 від 06 червня 2025 року | L11: 56.9 | M11: 56.9 | N11: 112 | O11: 221 | P11: 324.7 | Q11: 441 | R11: 538 | S11: 665 | T11: 884 | U11: 1086 | V11: 1 | W11: =M11-L11 -> 0 | X11: =N11-M11 -> 55.1 | Y11: =P11-O11 -> 103.7 | Z11: =Q11-P11 -> 116.3 | AA11: =R11-Q11 -> 97 | AB11: =S11-R11 -> 127 | AC11: =T11-S11 -> 219 | AD11: =U11-T11 -> 202 | AE11: 11.911944 | AF11: =V11*AD11*AE11 -> 2406.2127 | AH11: =1.2*9.92662 -> 11.911944
A12: л | B12: 6 | C12: м. Київ, вул. Сікорського Ігоря авіаконструктора, буд. 1-А | D12: ФОП Педаш С.В. | E12: электроэнергия | F12: 2798219324 | G12: 1 | H12: кавовий апарат | I12: 45392 | J12: № СУБ-24/М-6/2 від 10 квітня 2024 року | N12: 0 | O12: 0 | P12: 108 | Q12: 212 | R12: 329 | S12: 445 | T12: 558 | U12: 673 | V12: 1 | W12: =M12-L12 -> 0 | X12: =N12-M12 -> 0 | Y12: =P12-O12 -> 108 | Z12: =Q12-P12 -> 104 | AA12: =R12-Q12 -> 117 | AB12: =S12-R12 -> 116 | AC12: =T12-S12 -> 113 | AD12: =U12-T12 -> 115 | AE12: 11.891892 | AF12: =V12*AD12*AE12 -> 1367.5676 | AH12: =1.2*9.90991 -> 11.891892
A13: л | B13: 6 | C13: м. Київ, вул. Сікорського Ігоря авіаконструктора, буд. 1-А | D13: ФОП Ільєнко О.М. | E13: Вода | F13: 2653404868 | G13: 1 | H13: водомат | I13: 45689 | J13: № СУБ-25/ІОМ-Л від 01 лютого 2025 року | L13: 408 | M13: 438 | N13: 463 | O13: 484 | P13: 495.09 | Q13: 521 | R13: 558 | S13: 592 | T13: 641 | U13: 695 | V13: 1 | W13: =M13-L13 -> 30 | X13: =N13-M13 -> 25 | Y13: =P13-O13 -> 11.09 | Z13: =Q13-P13 -> 25.91 | AA13: =R13-Q13 -> 37 | AB13: =S13-R13 -> 34 | AC13: =T13-S13 -> 49 | AD13: =U13-T13 -> 54 | AE13: 54.505165 | AF13: =V13*AD13*AE13 -> 2943.2789
A14: р | B14: 9/1 | C14: м.Київ, вул. Сім'ї Ідзиковських, 4 | D14: ФОП Маркович О.П. | E14: Вода | F14: 2638518679 | G14: 1 | O14: 0 | P14: 1.79 | Q14: 7 | R14: 12.29 | S14: 18.81 | T14: 26.81 | U14: 34.05 | V14: 1 | Y14: =P14-O14 -> 1.79 | Z14: =Q14-P14 -> 5.21 | AA14: =R14-Q14 -> 5.29 | AB14: =S14-R14 -> 6.52 | AC14: =T14-S14 -> 8 | AD14: =U14-T14 -> 7.24 | AE14: 57.37543 | AF14: =V14*AD14*AE14 -> 415.39811
A15: л | B15: 10 | C15: м. Київ, проспект Героїв Сталінграда, 65-Б | D15: ФОП Ісаков А.О. | E15: электроэнергия | F15: 2915508435 | G15: 10 | H15: рибалка | I15: 45200 | J15: № ОР-23/М-10/1 від 01 жовтня 2023 року | L15: 7101 | M15: 7177 | N15: 7314 | O15: 7481 | P15: 7628 | Q15: 7706 | R15: 7814 | S15: 7856 | T15: 7964 | U15: 8058 | V15: 1 | W15: =M15-L15 -> 76 | X15: =N15-M15 -> 137 | Y15: =P15-O15 -> 147 | Z15: =Q15-P15 -> 78 | AA15: =R15-Q15 -> 108 | AB15: =S15-R15 -> 42 | AC15: =T15-S15 -> 108 | AD15: =U15-T15 -> 94 | AE15: 11.911944 | AF15: 1120
A16: л | B16: 10 | C16: м. Київ, проспект Героїв Сталінграда, 65-Б | D16: ФОП Хуторна А.М. | E16: электроэнергия | G16: 10 | H16: кофе-чай | L16: 53603 | M16: 54350 | N16: 55265 | O16: 56312 | P16: 57114 | Q16: 57785 | R16: 58312 | S16: 58818 | T16: 59401 | U16: 59401 | V16: 1 | W16: =M16-L16 -> 747 | X16: =N16-M16 -> 915 | Y16: =P16-O16 -> 802 | Z16: =Q16-P16 -> 671 | AA16: =R16-Q16 -> 527 | AB16: =S16-R16 -> 506 | AC16: =T16-S16 -> 583 | AD16: =U16-T16 -> 0 | AE16: =AE15 -> 11.911944 | AF16: =V16*AD16*AE16 -> 0
A17: л | B17: 10 | C17: м. Київ, проспект Героїв Сталінграда, 65-Б | E17: Вода | F17: 2880311305 | I17: 45778 | J17: № ОР-25/М-10/6 від 01 травня 2025 року | L17: 70 | M17: 72 | N17: 74 | O17: 75 | P17: 76 | Q17: 78 | R17: 80 | S17: 81 | T17: 83 | U17: 83 | V17: 1 | W17: =M17-L17 -> 2 | X17: =N17-M17 -> 2 | Y17: =P17-O17 -> 1 | Z17: =Q17-P17 -> 2 | AA17: =R17-Q17 -> 2 | AB17: =S17-R17 -> 1 | AC17: =T17-S17 -> 2 | AD17: =U17-T17 -> 0 | AE17: 49.98 | AF17: =V17*AD17*AE17 -> 0
A18: л | B18: 10 | C18: м. Київ, проспект Героїв Сталінграда, 65-Б | D18: ФОП Наумчук М.Г. | E18: электроэнергия | F18: 3388709882 | G18: 18 | H18: зоомагазин | I18: 45352 | J18: № ОР-24/М-10/2 від 01 березня 2024 року | L18: 13297 | M18: 13361 | N18: 13414 | O18: 13478 | P18: 13537 | Q18: 13591 | R18: 13644 | S18: 13697 | T18: 13743 | U18: 13883 | V18: 1 | W18: =M18-L18 -> 64 | X18: =N18-M18 -> 53 | Y18: =P18-O18 -> 59 | Z18: =Q18-P18 -> 54 | AA18: =R18-Q18 -> 53 | AB18: =S18-R18 -> 53 | AC18: =T18-S18 -> 46 | AD18: =U18-T18 -> 140 | AE18: =AE15 -> 11.911944 | AF18: =V18*AD18*AE18 -> 1667.6722
B19: 10 | C19: м. Київ, проспект Героїв Сталінграда, 65-Б | D19: ФОП Трегубова М.А. | E19: электроэнергия | F19: 3142718569 | S19: 1040 | T19: 1114 | U19: 1114 | V19: 1 | AC19: =T19-S19 -> 74 | AD19: =U19-T19 -> 0 | AE19: =AE16 -> 11.911944 | AF19: =V19*AD19*AE19 -> 0
A20: л | B20: 10 | C20: м. Київ, проспект Героїв Сталінграда, 65-Б | D20: ТОВ Массмарт | E20: электроэнергия | F20: 41747891 | G20: 130 | H20: белое/сухое | L20: 381253 | M20: 383658 | N20: 386424 | O20: 390122 | P20: 393305 | Q20: 395914 | R20: 398016 | S20: 399645 | T20: 401912 | U20: 404497 | V20: 1 | W20: =M20-L20 -> 2405 | X20: =N20-M20 -> 2766 | Y20: =P20-O20 -> 3183 | Z20: =Q20-P20 -> 2609 | AA20: =R20-Q20 -> 2102 | AB20: =S20-R20 -> 1629 | AC20: =T20-S20 -> 2267 | AD20: =U20-T20 -> 2585 | AE20: =AE15 -> 11.911944 | AF20: =V20*AD20*AE20 -> 30792.375
A21: л | B21: 10 | C21: м. Київ, проспект Героїв Сталінграда, 65-Б | E21: Вода | F21: 41747891 | I21: 45413 | J21: № ОР-24/М-10/3 від 01 травня 2024 року | L21: 1287 | M21: 1481 | N21: 1651 | O21: 1824 | P21: 1989 | Q21: 2161 | R21: 2282 | S21: 2525 | T21: 2782 | U21: 2940 | V21: 1 | W21: =M21-L21 -> 194 | X21: =N21-M21 -> 170 | Y21: =P21-O21 -> 165 | Z21: =Q21-P21 -> 172 | AA21: =R21-Q21 -> 121 | AB21: =S21-R21 -> 243 | AC21: =T21-S21 -> 257 | AD21: =U21-T21 -> 158 | AE21: =AE17 -> 49.98 | AF21: =V21*AD21*AE21 -> 7896.84
A22: р | B22: 11-1 | C22: м. Київ, вул. Автозаводська, 27 | D22: ФОП Ільєнко О.М. | E22: Вода | F22: 2653404868 | G22: 1 | H22: водомат | I22: 45689 | J22: № СУБ-25/ІОМ-Р від 01 лютого 2025 року | L22: 512.53 | M22: 532.35 | N22: 556 | O22: 579.72 | P22: 601.44 | Q22: 629.5 | R22: 654.2 | S22: 675.03 | T22: 698.24 | U22: 706.77 | V22: 1 | W22: =M22-L22 -> 19.82 | X22: =N22-M22 -> 23.65 | Y22: =P22-O22 -> 21.72 | Z22: =Q22-P22 -> 28.06 | AA22: =R22-Q22 -> 24.7 | AB22: =S22-R22 -> 20.83 | AC22: =T22-S22 -> 23.21 | AD22: =U22-T22 -> 8.53 | AE22: =AE21 -> 49.98 | AF22: =V22*AD22*AE22 -> 426.3294
A23: р | B23: 11-1 | C23: м. Київ, вул. Автозаводська, 27 | D23: ФОП Педаш С.В. | E23: электроэнергия | F23: 2798219324 | G23: 1 | H23: кавовий апарат | I23: 45392 | J23: № СУБ-24/М-11/1 від 10 квітня 2024 року | O23: 1 | P23: 39.9 | Q23: 140.2 | R23: 254.2 | S23: 369.4 | T23: 484.3 | U23: 644 | V23: 1 | W23: =M23-L23 -> 0 | X23: =N23-M23 -> 0 | Y23: =P23-O23 -> 38.9 | Z23: =Q23-P23 -> 100.3 | AA23: =R23-Q23 -> 114 | AB23: =S23-R23 -> 115.2 | AC23: =T23-S23 -> 114.9 | AD23: =U23-T23 -> 159.7 | AE23: 11.91194 | AF23: =V23*AD23*AE23 -> 1902.3368
A24: л | B24: 12 | C24: м. Київ, вул. Антоновича, 115-Д | D24: ТОВ Лайфселл | E24: электроэнергия | F24: 22859846 | G24: 3 | H24: антенна | I24: 44986 | J24: № М12-СО від 01 березня 2023 року | L24: 40619 | M24: 41398.3 | N24: 42138 | O24: 42877.9 | P24: 0 | Q24: 585.91 | R24: 1303.9 | S24: 1994.92 | T24: 2689.01 | U24: 3416.2 | V24: 1 | W24: =M24-L24 -> 779.3 | X24: =N24-M24 -> 739.7 | Y24: 790 | Z24: 710 | AA24: =R24-Q24 -> 717.99 | AB24: =S24-R24 -> 691.02 | AC24: =T24-S24 -> 694.09 | AD24: =U24-T24 -> 727.19 | AE24: 11.91194 | AF24: =V24*AD24*AE24 -> 8662.2436
A25: л | B25: 12 | C25: м. Київ, вул. Антоновича, 115-Д | D25: ТОВ "Юкрейн Таувер Компані" | E25: электроэнергия | F25: 44281999 | G25: 3 | H25: антенна | I25: 45693 | J25: № TUA3725 від 05 лютого 2025 року | L25: 27659.7 | M25: 28621.5 | N25: 29610 | O25: 30601.6 | P25: 31668.7 | Q25: 33065.1 | R25: 34631.1 | S25: 36331.5 | T25: 38033.1 | U25: 39692.8 | V25: 1 | W25: =M25-L25 -> 961.8 | X25: =N25-M25 -> 988.5 | Y25: =P25-O25 -> 1067.1 | Z25: =Q25-P25 -> 1396.4 | AA25: =R25-Q25 -> 1566 | AB25: =S25-R25 -> 1700.4 | AC25: =T25-S25 -> 1701.6 | AD25: =U25-T25 -> 1659.7 | AE25: =AE24 -> 11.91194 | AF25: =V25*AD25*AE25 -> 19770.247
A26: р | B26: 13-1 | C26: Київська обл., Києво-Святошинський район, с. Тарасівка, вул. Братів Чмілів, буд. 3-А | D26: ФОП Басов Е. А. | E26: Вода | F26: 2634610713 | G26: 1 | H26: водомат | I26: 45627 | J26: № СУБ-24/БЕА-Р від 01 грудня 2024 року | L26: 1126 | M26: 1143 | N26: 1158 | O26: 1174 | P26: 1194 | Q26: 1220 | R26: 1237 | S26: 1259 | T26: 1283 | U26: 1309 | V26: 1 | W26: =M26-L26 -> 17 | X26: =N26-M26 -> 15 | Y26: =P26-O26 -> 20 | Z26: =Q26-P26 -> 26 | AA26: =R26-Q26 -> 17 | AB26: =S26-R26 -> 22 | AC26: =T26-S26 -> 24 | AD26: =U26-T26 -> 26 | AE26: 108.33048 | AF26: =V26*AD26*AE26 -> 2816.5924
A27: р | B27: 13-1 | C27: Київська обл., Києво-Святошинський район, с. Тарасівка, вул. Братів Чмілів, буд. 3-А | D27: ФОП Литвиненко О.М. | E27: электроэнергия | F27: 2959508626 | G27: 40 | H27: зоотовары и моб.аксессуары | I27: 45627 | J27: № СУБ-24/М-13/2 від 01 грудня 2024 року | L27: 12469 | M27: 12636 | N27: 12819 | O27: 12990 | P27: 13168 | Q27: 13349 | R27: 13515 | S27: 13733 | T27: 13931 | U27: 14230 | V27: 1 | W27: =M27-L27 -> 167 | X27: =N27-M27 -> 183 | Y27: =P27-O27 -> 178 | Z27: =Q27-P27 -> 181 | AA27: =R27-Q27 -> 166 | AB27: =S27-R27 -> 218 | AC27: =T27-S27 -> 198 | AD27: =U27-T27 -> 299 | AE27: 12.197472 | AF27: =V27*AD27*AE27 -> 3647.0441 | AH27: =1.2*10.16456 -> 12.197472
A28: р | B28: 13-1 | C28: Київська обл., Києво-Святошинський район, с. Тарасівка, вул. Братів Чмілів, буд. 3-А | E28: Вода | L28: 33 | M28: 34 | N28: 35 | O28: 36 | P28: 37 | Q28: 40 | R28: 41 | S28: 43 | T28: 46 | U28: 48 | V28: 1 | W28: =M28-L28 -> 1 | X28: =N28-M28 -> 1 | Y28: =P28-O28 -> 1 | Z28: =Q28-P28 -> 3 | AA28: =R28-Q28 -> 1 | AB28: =S28-R28 -> 2 | AC28: =T28-S28 -> 3 | AD28: =U28-T28 -> 2 | AE28: =AE26 -> 108.33048 | AF28: =V28*AD28*AE28 -> 216.66095
A29: р | B29: 13-1 | C29: Київська обл., Києво-Святошинський район, с. Тарасівка, вул. Братів Чмілів, буд. 3-А | D29: ФОП Войтов П.О. | E29: электроэнергия | F29: 3081921694 | G29: 1 | H29: кавовий апарат | I29: 45793 | J29: № СУБ-25/М-13/1 від 16 травня 2025 року | M29: 0 | N29: 0 | O29: 53.2 | P29: 106 | Q29: 160 | R29: 211 | S29: 254 | T29: 289 | U29: 375 | V29: 1 | W29: =M29-L29 -> 0 | X29: =N29-M29 -> 0 | Y29: =P29-O29 -> 52.8 | Z29: =Q29-P29 -> 54 | AA29: =R29-Q29 -> 51 | AB29: =S29-R29 -> 43 | AC29: =T29-S29 -> 35 | AD29: =U29-T29 -> 86 | AE29: =AE27 -> 12.197472 | AF29: =V29*AD29*AE29 -> 1048.9826
A30: л | B30: 14 | C30: м. Київ, вул. Світла, буд. 3-Д, корп. 1, приміщення 2013 | D30: ФОП Ридван І. Г. | E30: Вода | F30: 3016517362 | G30: 1 | H30: водомат | I30: 45627 | J30: № СУБ-24/РІГ-Л від 01 грудня 2024 року | L30: 2684 | M30: 2697 | N30: 2708 | O30: 2718 | P30: 2729 | Q30: 2741 | R30: 2752 | S30: 2765 | T30: 2776.3 | U30: 2785 | V30: 1 | W30: =M30-L30 -> 13 | X30: =N30-M30 -> 11 | Y30: =P30-O30 -> 11 | Z30: =Q30-P30 -> 12 | AA30: =R30-Q30 -> 11 | AB30: =S30-R30 -> 13 | AC30: =T30-S30 -> 11.3 | AD30: =U30-T30 -> 8.7 | AE30: 49.98 | AF30: =V30*AD30*AE30 -> 434.826
A31: л | B31: 15 | C31: м. Київ, вул. Шолом-Алейхема, буд. 10-А | D31: ФОП Ільєнко О.М. | E31: Вода | F31: 2653404868 | G31: 1 | H31: водомат | I31: 45689 | J31: № ОР-25/ІОМ від 01 лютого 2025 року | L31: 1226.76 | M31: 1233.82 | N31: 1240.9 | O31: 1247.61 | P31: 1253.3 | Q31: 1259.99 | R31: 1267.74 | S31: 1273.46 | T31: 1281.66 | U31: 1291.54 | V31: 1 | W31: =M31-L31 -> 7.06 | X31: =N31-M31 -> 7.08 | Y31: =P31-O31 -> 5.69 | Z31: =Q31-P31 -> 6.69 | AA31: =R31-Q31 -> 7.75 | AB31: =S31-R31 -> 5.72 | AC31: =T31-S31 -> 8.2 | AD31: =U31-T31 -> 9.88 | AE31: 54.89 | AF31: =V31*AD31*AE31 -> 542.3132
A32: л | B32: 15 | C32: м. Київ, вул. Шолом-Алейхема, буд. 10-А | D32: ТОВ ПНМЕК "ТОКА" | E32: электроэнергия | F32: 40062282 | G32: 1 | H32: электрозаправка | I32: 45261 | J32: № ОР-23/М-15/1 від 01 грудня 2023 року | L32: 36811.16 | M32: 37019.03 | N32: 37204.34 | O32: 37633.31 | P32: 38273.78 | Q32: 38855.12 | R32: 39731.75 | S32: 40076.7 | T32: 40952.94 | U32: 41432.1 | V32: 1 | W32: =M32-L32 -> 207.87 | X32: =N32-M32 -> 185.31 | Y32: =P32-O32 -> 640.47 | Z32: =Q32-P32 -> 581.34 | AA32: =R32-Q32 -> 876.63 | AB32: =S32-R32 -> 344.95 | AC32: =T32-S32 -> 876.24 | AD32: =U32-T32 -> 479.16 | AE32: 11.974956 | AF32: =V32*AD32*AE32 -> 5737.9199 | AH32: =1.2*9.97913 -> 11.974956
A33: л | B33: 15 | C33: м. Київ, вул. Шолом-Алейхема, буд. 10-А | D33: ПАТ Київстар | E33: электроэнергия | F33: 21673832 | G33: 5 | H33: антенна | I33: 45292 | J33: № 01/01/2024 -СО від 01 січня 2024 року | L33: 59790.7 | M33: 61444.2 | N33: 63020.3 | O33: 64712.1 | P33: 66329.9 | Q33: 67879.5 | R33: 69545.7 | S33: 70902.4 | T33: 72474.9 | U33: 74774.5 | V33: 1 | W33: =M33-L33 -> 1653.5 | X33: =N33-M33 -> 1576.1 | Y33: =P33-O33 -> 1617.8 | Z33: =Q33-P33 -> 1549.6 | AA33: =R33-Q33 -> 1666.2 | AB33: =S33-R33 -> 1356.7 | AC33: =T33-S33 -> 1572.5 | AD33: =U33-T33 -> 2299.6 | AE33: =AE32 -> 11.974956 | AF33: =V33*AD33*AE33 -> 27537.609
A34: л | B34: 15 | C34: м. Київ, вул. Шолом-Алейхема, буд. 10-А | D34: ТОВ Лайфселл | E34: электроэнергия | F34: 22859846 | G34: 3 | H34: антенна | I34: 44986 | J34: № М15-О від 01 березня 2023 року | L34: 53920 | M34: 53952 | N34: 54720.4 | O34: 55532.4 | P34: 56314.5 | Q34: 57081.7 | R34: 57935 | S34: 58458 | T34: 59028.6 | U34: 59545.6 | V34: 1 | W34: =M34-L34 -> 32 | X34: =N34-M34 -> 768.4 | Y34: =P34-O34 -> 782.1 | Z34: =Q34-P34 -> 767.2 | AA34: =R34-Q34 -> 853.3 | AB34: =S34-R34 -> 523 | AC34: =T34-S34 -> 570.6 | AD34: =U34-T34 -> 517 | AE34: =AE32 -> 11.974956 | AF34: =V34*AD34*AE34 -> 6191.0523
A35: л | B35: 15 | C35: м. Київ, вул. Шолом-Алейхема, буд. 10-А | D35: ПАТ "ВФ Україна" | E35: электроэнергия | F35: 14333937 | G35: 3 | H35: антенна | I35: 45231 | J35: № RC-23-510915 від 01 листопада 2023 року | L35: 25688.46 | M35: 27199.04 | N35: 28620.33 | O35: 30197.49 | P35: 31708.06 | Q35: 33188.43 | R35: 34848.64 | S35: 36078.44 | T35: 37493.99 | U35: 38672.72 | V35: 1 | W35: =M35-L35 -> 1510.58 | X35: =N35-M35 -> 1421.29 | Y35: =P35-O35 -> 1510.57 | Z35: =Q35-P35 -> 1480.37 | AA35: =R35-Q35 -> 1660.21 | AB35: =S35-R35 -> 1229.8 | AC35: =T35-S35 -> 1415.55 | AD35: =U35-T35 -> 1178.73 | AE35: =AE32 -> 11.974956 | AF35: =V35*AD35*AE35 -> 14115.24
A36: л | B36: 15 | C36: м. Київ, вул. Шолом-Алейхема, буд. 10-А | D36: ТОВ "ЕКО ВОДА" | E36: электроэнергия | F36: 40971728 | G36: 8 | H36: пункт разлива воды | I36: 45371 | J36: № ОР-24/М-15/2 від 20 березня 2024 року | L36: 3699.9 | M36: 3882.6 | N36: 4071.4 | O36: 4291.4 | P36: 4491.2 | Q36: 4686.9 | R36: 4949.5 | S36: 5285.7 | T36: 5904.1 | U36: 6608.6 | V36: 1 | W36: =M36-L36 -> 182.7 | X36: =N36-M36 -> 188.8 | Y36: =P36-O36 -> 199.8 | Z36: =Q36-P36 -> 195.7 | AA36: =R36-Q36 -> 262.6 | AB36: =S36-R36 -> 336.2 | AC36: =T36-S36 -> 618.4 | AD36: =U36-T36 -> 704.5 | AE36: =AE32 -> 11.974956 | AF36: =V36*AD36*AE36 -> 8436.3565
A37: л | B37: 15 | C37: м. Київ, вул. Шолом-Алейхема, буд. 10-А | E37: Вода | L37: 608.1 | M37: 672.02 | N37: 742.88 | O37: 826.7 | P37: 897.38 | Q37: 971.68 | R37: 1058.75 | S37: 1134.44 | T37: 1228.98 | U37: 1314.13 | V37: 1 | W37: =M37-L37 -> 63.92 | X37: =N37-M37 -> 70.86 | Y37: =P37-O37 -> 70.68 | Z37: =Q37-P37 -> 74.3 | AA37: =R37-Q37 -> 87.07 | AB37: =S37-R37 -> 75.69 | AC37: =T37-S37 -> 94.54 | AD37: =U37-T37 -> 85.15 | AE37: =AE31 -> 54.89 | AF37: =V37*AD37*AE37 -> 4673.8835
A38: л | B38: 15 | C38: м. Київ, вул. Шолом-Алейхема, буд. 10-А | D38: ФОП Ковальова А.О. | E38: электроэнергия | F38: 3380916566 | G38: 1 | H38: кавовий апарат | I38: 45474 | J38: № ОР-24/М-15/3 від 01 липня 2024 року | M38: 1.5 | N38: 1.5 | O38: 5.4 | P38: 69.5 | Q38: 132.9 | R38: 182.3 | S38: 182.3 | T38: 240.7 | U38: 285.9 | V38: 1 | W38: =M38-L38 -> 1.5 | X38: =N38-M38 -> 0 | Y38: =P38-O38 -> 64.1 | Z38: =Q38-P38 -> 63.4 | AA38: =R38-Q38 -> 49.4 | AB38: =S38-R38 -> 0 | AC38: =T38-S38 -> 58.4 | AD38: =U38-T38 -> 45.2 | AE38: =AE34 -> 11.974956 | AF38: =V38*AD38*AE38 -> 541.26801
A39: р | B39: 17-1 | C39: Київська обл., Бориспільський район, м. Бориспіль, вулиця Головатого, 64, приміщення 156 | D39: ФОП Ткач Ю.С. | E39: электроэнергия | F39: 3704207084 | G39: 1 | H39: кавовий апарат | I39: 45336 | J39: № СУБ-24/М-17/2 від 14 лютого 2024 року | V39: 1 | W39: =M39-L39 -> 0 | X39: =N39-M39 -> 0 | Y39: =P39-O39 -> 0 | Z39: =Q39-P39 -> 0 | AA39: =R39-Q39 -> 0 | AB39: =S39-R39 -> 0 | AC39: =T39-S39 -> 0 | AD39: =U39-T39 -> 0 | AE39: -
A40: л | B40: 18 | C40: м. Київ, вул. Челябінська, 15-А | D40: ФОП Ридван І. Г. | E40: Вода | F40: 3016517362 | G40: 1 | H40: водомат | I40: 45627 | J40: № СУБ-24/РІГ-Л від 01 грудня 2024 року | L40: 1014.5 | M40: 1020.45 | N40: 1024.81 | O40: 1029.63 | P40: 1034.93 | Q40: 1039.11 | R40: 1041.78 | S40: 1044.19 | T40: 1046.24 | U40: 1048.25 | V40: 1 | W40: =M40-L40 -> 5.95 | X40: =N40-M40 -> 4.36 | Y40: =P40-O40 -> 5.3 | Z40: =Q40-P40 -> 4.18 | AA40: =R40-Q40 -> 2.67 | AB40: =S40-R40 -> 2.41 | AC40: =T40-S40 -> 2.05 | AD40: =U40-T40 -> 2.01 | AE40: 52.979167 | AF40: =V40*AD40*AE40 -> 106.48812
A41: л | B41: 18 | C41: м. Київ, вул. Челябінська, 15-А | D41: ФОП Шамахмудов Р.Х. | E41: электроэнергия | F41: 2912901337 | G41: 1 | H41: кавовий апарат | I41: 45775 | J41: № СУБ-25/М-18/2 від 28 квітня 2025 року | L41: 182 | M41: 288.6 | N41: 398 | O41: 534 | P41: 661.6 | Q41: 778.8 | R41: 893.5 | S41: 991.7 | T41: 1090.3 | U41: 1090.3 | V41: 1 | W41: =M41-L41 -> 106.6 | X41: =N41-M41 -> 109.4 | Y41: =P41-O41 -> 127.6 | Z41: =Q41-P41 -> 117.2 | AA41: =R41-Q41 -> 114.7 | AB41: =S41-R41 -> 98.2 | AC41: =T41-S41 -> 98.6 | AD41: =U41-T41 -> 0 | AE41: 12.779568 | AF41: =V41*AD41*AE41 -> 0 | AH41: =1.2*10.64964 -> 12.779568
...

Sheet М3
O1: Предприятие
A2: Расход электроэнергии/воды за август 2023г. | O2: Легіон 2015
A3: Местоположение: | C3: М34 магазин "Пчелка маркет" г. Киев, ул. Р.Окипной, 3
L4: з ПДВ
A5: № п/п | B5: Название потребителя | C5: Юридическое лицо | D5: № счетчика | E5: Энергоноситель | F5: Показатели счетчика | J5: Коэф. | K5: Потребление, кВт/ч, м3/ч | L5: Стоимость 1кВт/ч, м3/ч | M5: Итого
F6: Дата снятия | G6: Показатели | H6: Дата снятия | I6: Показатели
A7: 1 | B7: Субпотребитель | C7: ТОВ "Аврора" | D7: НІК 2303 АРП1 №0222299 | E7: Активная э.э. | F7: 45138 | G7: 59884.28 | H7: 45170 | I7: 60012.64 | J7: 1 | K7: =I7-G7 -> 128.36 | L7: 6.610763 | M7: =K7*L7*J7 -> 848.55753
L9: ИТОГО: | M9: =SUM(M7:M7) -> 848.55753 | N9: грн.
A10: Расход электроэнергии/воды за сентябр 2023г. | O10: Легіон 2015
A11: Местоположение: | C11: М3 магазин "Пчелка маркет" г. Киев, ул. Р.Окипной, 3
A13: № п/п | B13: Название потребителя | C13: Юридическое лицо | D13: № счетчика | E13: Энергоноситель | F13: Показатели счетчика | J13: Коэф. | K13: Потребление, кВт/ч, м3/ч | L13: Стоимость 1кВт/ч, м3/ч | M13: Итого
F14: Дата снятия | G14: Показатели | H14: Дата снятия | I14: Показатели
A15: 1 | B15: Субпотребитель | C15: ТОВ "Аврора" | D15: НІК 2303 АРП1 №0222299 | E15: Активная э.э. | F15: 45170 | G15: 60012.64 | H15: 45170 | I15: 61391.57 | J15: 1 | K15: =I15-G15 -> 1378.93 | L15: 6.3494518 | M15: =K15*L15*J15 -> 8755.4496
L17: ИТОГО: | M17: =SUM(M15:M15) -> 8755.4496 | N17: грн.
O18: Легіон 2015
A19: Расход электроэнергии/воды за октябрь 2023г.
A20: Местоположение: | C20: М3 магазин "Пчелка маркет" г. Киев, ул. Р.Окипной, 3
A22: № п/п | B22: Название потребителя | C22: Юридическое лицо | D22: № счетчика | E22: Энергоноситель | F22: Показатели счетчика | J22: Коэф. | K22: Потребление, кВт/ч, м3/ч | L22: Стоимость 1кВт/ч, м3/ч | M22: Итого
F23: Дата снятия | G23: Показатели | H23: Дата снятия | I23: Показатели
A24: 1 | B24: Субпотребитель | C24: ТОВ "Аврора" | D24: НІК 2303 АРП1 №0222299 | E24: Активная э.э. | F24: 45170 | G24: 61391.57 | H24: 45230 | I24: 62937.75 | J24: 1 | K24: =I24-G24 -> 1546.18 | L24: 6.25944 | M24: =K24*L24*J24 -> 9678.2209
L26: ИТОГО: | M26: =SUM(M24:M24) -> 9678.2209 | N26: грн.
A28: Расход электроэнергии/воды за ноябрь 2023г.
A29: Местоположение: | C29: М3 магазин "Пчелка маркет" г. Киев, ул. Р.Окипной, 3
A31: № п/п | B31: Название потребителя | C31: Юридическое лицо | D31: № счетчика | E31: Энергоноситель | F31: Показатели счетчика | J31: Коэф. | K31: Потребление, кВт/ч, м3/ч | L31: Стоимость 1кВт/ч, м3/ч | M31: Итого
F32: Дата снятия | G32: Показатели | H32: Дата снятия | I32: Показатели
A33: 1 | B33: Субпотребитель | C33: ТОВ "Аврора" | D33: НІК 2303 АРП1 №0222299 | E33: Активная э.э. | F33: 45230 | G33: 62937.75 | H33: 45260 | I33: 64806.42 | J33: 1 | K33: =I33-G33 -> 1868.67 | L33: 6.7596598 | M33: =K33*L33*J33 -> 12631.574
L35: ИТОГО: | M35: =SUM(M33:M33) -> 12631.574 | N35: грн.
B36: Отправили счет на ФОП "Воробйова"
A37: Расход электроэнергии/воды за декабрь 2023г.
A38: Местоположение: | C38: М3 магазин "Пчелка маркет" г. Киев, ул. Р.Окипной, 3
A40: № п/п | B40: Название потребителя | C40: Юридическое лицо | D40: № счетчика | E40: Энергоноситель | F40: Показатели счетчика | J40: Коэф. | K40: Потребление, кВт/ч, м3/ч | L40: Стоимость 1кВт/ч, м3/ч | M40: Итого
F41: Дата снятия | G41: Показатели | H41: Дата снятия | I41: Показатели
A42: 1 | B42: Субпотребитель | C42: ТОВ "Аврора" | D42: НІК 2303 АРП1 №0222299 | E42: Активная э.э. | F42: 45260 | G42: 64806.42 | H42: 45291 | I42: 67341.92 | J42: 1 | K42: =I42-G42 -> 2535.5 | L42: 6.4951202 | M42: =K42*L42*J42 -> 16468.377
L44: ИТОГО: | M44: =SUM(M42:M42) -> 16468.377 | N44: грн.
A46: Расход электроэнергии/воды за январь 2024 г.
A47: Местоположение: | C47: М3 магазин "Пчелка маркет" г. Киев, ул. Р.Окипной, 3
A49: № п/п | B49: Название потребителя | C49: Юридическое лицо | D49: № счетчика | E49: Энергоноситель | F49: Показатели счетчика | J49: Коэф. | K49: Потребление, кВт/ч, м3/ч | L49: Стоимость 1кВт/ч, м3/ч | M49: Итого
F50: Дата снятия | G50: Показатели | H50: Дата снятия | I50: Показатели
A51: 1 | B51: Субпотребитель | C51: ТОВ "Аврора" | D51: НІК 2303 АРП1 №0222299 | E51: Активная э.э. | F51: 45291 | G51: 67341.92 | H51: 45323 | I51: 70250.76 | J51: 1 | K51: =I51-G51 -> 2908.84 | L51: =[2]Арендаторы!M15 -> #REF! | M51: =K51*L51*J51 -> #REF!
L53: ИТОГО: | M53: =SUM(M51:M51) -> #REF! | N53: грн.
...

Sheet М5
B3: Расход электроэнергии/воды за февраль-ноябрь 2022г.
B4: Местоположение: | E4: М5 магазин "Пчелка маркет" г. Киев, ул. Коласа Якуба, 2A
B6: № п/п | C6: Название потребителя | D6: Юридическое лицо | E6: № счетчика | F6: Энергоноситель | G6: Показатели счетчика | K6: Коэф. | L6: Потребление, кВт/ч, м3/ч | M6: Стоимость 1кВт/ч, м3/ч | N6: Итого
G7: Дата снятия | H7: Показатели | I7: Дата снятия | J7: Показатели
B8: 1 | C8: Спортивный клуб | E8: Энергомера ЦЭ68038 №60142331 | F8: Активная э.э. | G8: 44593 | H8: 214140 | I8: 44896 | J8: 214528 | K8: 1 | L8: =J8-H8 -> 388 | M8: 4.9663925 | N8: =L8*M8 -> 1926.9603
E9: JS 2,5-02 №13749754 | F9: Водоснабжение | G9: 44593 | H9: 1525 | I9: 44896 | J9: 1550.69 | K9: 1 | L9: =J9-H9 -> 25.69 | M9: 30.38 | N9: =L9*M9 -> 780.4622
B10: 2 | C10: Магазин инструментов ТМ "Makita" | E10: CO-ЭЭ6706 №054494008 | F10: Активная э.э. | G10: 44593 | H10: 16853 | I10: 44896 | J10: 17993 | K10: 1 | L10: =J10-H10 -> 1140 | M10: =M8 -> 4.9663925 | N10: =L10*M10 -> 5661.6875
B11: 3 | C11: Помещение электрощитовой | E11: НІК 2102-02.M2 №4921123 | F11: Активная э.э. | G11: 44866 | H11: 28080.8 | I11: 44896 | J11: 28096.3 | K11: 1 | L11: =J11-H11 -> 15.5 | M11: =M8 -> 4.9663925 | N11: =L11*M11 -> 76.979084
H12: Потребление, кВт/ч, м3/ч | I12: Стоимость 1кВт/ч, м3/ч | J12: Итого
G13: Фев.-дек.2022 | H13: =10*8.24 -> 82.4 | I13: 30.38 | J13: =H13*I13 -> 2503.312
B15: Расход электроэнергии/воды за декабрь 2022г.
B16: Местоположение: | E16: М5 магазин "Пчелка маркет" г. Киев, ул. Коласа Якуба, 2A
B18: № п/п | C18: Название потребителя | D18: Юридическое лицо | E18: № счетчика | F18: Энергоноситель | G18: Показатели счетчика | K18: Коэф. | L18: Потребление, кВт/ч, м3/ч | M18: Стоимость 1кВт/ч, м3/ч | N18: Итого
G19: Дата снятия | H19: Показатели | I19: Дата снятия | J19: Показатели
B20: 1 | C20: Спортивный клуб | E20: Энергомера ЦЭ68038 №60142331 | F20: Активная э.э. | G20: 44896 | H20: 214528 | I20: 44927 | J20: 214942 | K20: 1 | L20: =J20-H20 -> 414 | M20: =M8 -> 4.9663925 | N20: =L20*M20 -> 2056.0865
E21: JS 2,5-02 №13749754 | F21: Водоснабжение | G21: 44593 | H21: 1550.69 | I21: 44924 | J21: 1558.93 | K21: 1 | L21: =J21-H21 -> 8.24 | M21: 30.38 | N21: =L21*M21 -> 250.3312
B22: 2 | C22: Магазин инструментов ТМ "Makita" | E22: CO-ЭЭ6706 №054494008 | F22: Активная э.э. | G22: 44896 | H22: 17993 | I22: 44927 | J22: 18109 | K22: 1 | L22: =J22-H22 -> 116 | M22: =M20 -> 4.9663925 | N22: =L22*M22 -> 576.10153
B23: 3 | C23: Помещение электрощитовой | E23: НІК 2102-02.M2 №4921123 | F23: Активная э.э. | G23: 44866 | H23: 28096.3 | I23: 44927 | J23: 28112.3 | K23: 1 | L23: =J23-H23 -> 16 | M23: =M20 -> 4.9663925 | N23: =L23*M23 -> 79.46228
B26: Расход электроэнергии/воды за январь 2023г.
B27: Местоположение: | E27: М5 магазин "Пчелка маркет" г. Киев, ул. Коласа Якуба, 2A
B29: № п/п | C29: Название потребителя | D29: Юридическое лицо | E29: № счетчика | F29: Энергоноситель | G29: Показатели счетчика | K29: Коэф. | L29: Потребление, кВт/ч, м3/ч | M29: Стоимость 1кВт/ч, м3/ч | N29: Итого
G30: Дата снятия | H30: Показатели | I30: Дата снятия | J30: Показатели
B31: 1 | C31: Спортивный клуб | E31: Энергомера ЦЭ68038 №60142331 | F31: Активная э.э. | G31: 44927 | H31: 214942 | I31: 44957 | J31: 215023 | K31: 1 | L31: =J31-H31 -> 81 | M31: =M20 -> 4.9663925 | N31: =L31*M31 -> 402.27779
E32: JS 2,5-02 №13749754 | F32: Водоснабжение | G32: 44924 | H32: 1558.93 | I32: 44957 | J32: 1567.17 | K32: 1 | L32: =J32-H32 -> 8.24 | M32: 30.38 | N32: =L32*M32 -> 250.3312
B33: 2 | C33: Магазин инструментов ТМ "Makita" | E33: CO-ЭЭ6706 №054494008 | F33: Активная э.э. | G33: 44927 | H33: 18109 | I33: 44957 | J33: 18201.9 | K33: 1 | L33: =J33-H33 -> 92.9 | M33: =M31 -> 4.9663925 | N33: =L33*M33 -> 461.37786
B34: 3 | C34: Помещение электрощитовой | E34: НІК 2102-02.M2 №4921123 | F34: Активная э.э. | G34: 44926 | H34: 28112.3 | I34: 44957 | J34: 28126.8 | K34: 1 | L34: =J34-H34 -> 14.5 | M34: =M31 -> 4.9663925 | N34: =L34*M34 -> 72.012691
B36: Расход электроэнергии/воды за февраль 2023г.
B37: Местоположение: | E37: М5 магазин "Пчелка маркет" г. Киев, ул. Коласа Якуба, 2A
B39: № п/п | C39: Название потребителя | D39: Юридическое лицо | E39: № счетчика | F39: Энергоноситель | G39: Показатели счетчика | K39: Коэф. | L39: Потребление, кВт/ч, м3/ч | M39: Стоимость 1кВт/ч, м3/ч | N39: Итого
G40: Дата снятия | H40: Показатели | I40: Дата снятия | J40: Показатели
B41: 1 | C41: Спортивный клуб | E41: Энергомера ЦЭ68038 №60142331 | F41: Активная э.э. | G41: 44957 | H41: 215023 | I41: 44985 | J41: 215093 | K41: 1 | L41: =J41-H41 -> 70 | M41: =M8 -> 4.9663925 | N41: =L41*M41 -> 347.64748
E42: JS 2,5-02 №13749754 | F42: Водоснабжение | G42: 44957 | H42: 1567.17 | I42: 44985 | J42: 1573.1 | K42: 1 | L42: =J42-H42 -> 5.93 | M42: 30.446 | N42: =L42*M42 -> 180.54478
B43: 2 | C43: Магазин инструментов ТМ "Makita" | E43: CO-ЭЭ6706 №054494008 | F43: Активная э.э. | G43: 44957 | H43: 18201.9 | I43: 44957 | J43: 18201.9 | K43: 1 | L43: =J43-H43 -> 0 | M43: =M8 -> 4.9663925 | N43: =L43*M43 -> 0
B44: 3 | C44: Помещение электрощитовой | E44: НІК 2102-02.M2 №4921123 | F44: Активная э.э. | G44: 44957 | H44: 28126.8 | I44: 44985 | J44: 28126.8 | K44: 1 | L44: =J44-H44 -> 0 | M44: =M8 -> 4.9663925 | N44: =L44*M44 -> 0
B46: Расход электроэнергии/воды за март 2023г.
B47: Местоположение: | E47: М5 магазин "Пчелка маркет" г. Киев, ул. Коласа Якуба, 2A
B49: № п/п | C49: Название потребителя | D49: Юридическое лицо | E49: № счетчика | F49: Энергоноситель | G49: Показатели счетчика | K49: Коэф. | L49: Потребление, кВт/ч, м3/ч | M49: Стоимость 1кВт/ч, м3/ч | N49: Итого
G50: Дата снятия | H50: Показатели | I50: Дата снятия | J50: Показатели
B51: 1 | C51: Спортивный клуб | E51: Энергомера ЦЭ68038 №60142331 | F51: Активная э.э. | G51: 44985 | H51: 215093 | I51: 45016 | J51: 215369 | K51: 1 | L51: =J51-H51 -> 276 | M51: 5.148 | N51: =L51*M51 -> 1420.848
E52: JS 2,5-02 №13749754 | F52: Водоснабжение | G52: 44985 | H52: 1573.1 | I52: 45016 | J52: 1580.01 | K52: 1 | L52: =J52-H52 -> 6.91 | M52: 30.446 | N52: =L52*M52 -> 210.38186
...

Sheet М11
B4: Расход электроэнергии/воды за декабрь 2023г.
B5: Местоположение: | E5: М11 магазин "Пчелка маркет" г. Киев, Автозаводська,27
B7: № п/п | C7: Название потребителя | D7: Юридическое лицо | E7: № счетчика | F7: Энергоноситель | G7: Показатели счетчика | K7: Коэф. | L7: Потребление, кВт/ч, м3/ч | M7: Стоимость 1кВт/ч, м3/ч | N7: Итого
G8: Дата снятия | H8: Показатели | I8: Дата снятия | J8: Показатели
B9: 1 | C9: ФОП ЧАХОЯН ГАЙК ЕДВАРДОВИЧ | E9: (ТП) NIK 2303 ARP1 №0198983 | F9: Активня э.э. | G9: 45291 | H9: 173.08 | I9: 45322 | J9: 219.81 | K9: 30 | L9: =J9-H9 -> 46.73 | M9: 6.3746284 | N9: =M9*L9*K9 -> 8936.5915
M10: ИТОГО: | N10: =SUM(N9) -> 8936.5915 | O10: грн.
B13: Расход электроэнергии/воды за январь 2024г.
B14: Местоположение: | E14: М11 магазин "Пчелка маркет" г. Киев, Автозаводська,27
B16: № п/п | C16: Название потребителя | D16: Юридическое лицо | E16: № счетчика | F16: Энергоноситель | G16: Показатели счетчика | K16: Коэф. | L16: Потребление, кВт/ч, м3/ч | M16: Стоимость 1кВт/ч, м3/ч | N16: Итого
G17: Дата снятия | H17: Показатели | I17: Дата снятия | J17: Показатели
B18: 1 | C18: ФОП ЧАХОЯН ГАЙК ЕДВАРДОВИЧ | E18: (ТП) NIK 2303 ARP1 №0198983 | F18: Активня э.э. | G18: 45291 | H18: 219.81 | I18: 45322 | J18: 270.6 | K18: 30 | L18: =J18-H18 -> 50.79 | M18: 6.02688 | N18: =M18*L18*K18 -> 9183.1571
M19: ИТОГО: | N19: =SUM(N18) -> 9183.1571 | O19: грн.
B20: Расход электроэнергии/воды за февраль 2024г.
B21: Местоположение: | E21: М11 магазин "Пчелка маркет" г. Киев, Автозаводська,27
B23: № п/п | C23: Название потребителя | D23: Юридическое лицо | E23: № счетчика | F23: Энергоноситель | G23: Показатели счетчика | K23: Коэф. | L23: Потребление, кВт/ч, м3/ч | M23: Стоимость 1кВт/ч, м3/ч | N23: Итого
G24: Дата снятия | H24: Показатели | I24: Дата снятия | J24: Показатели
B25: 1 | C25: ФОП ЧАХОЯН ГАЙК ЕДВАРДОВИЧ | E25: (ТП) NIK 2303 ARP1 №0198983 | F25: Активня э.э. | G25: 45322 | H25: 270.6 | I25: 31.02.2024 | J25: 310.53 | K25: 30 | L25: =J25-H25 -> 39.93 | M25: 5.4806882 | N25: =M25*L25*K25 -> 6565.3164
M26: ИТОГО: | N26: =SUM(N25) -> 6565.3164 | O26: грн.
B27: Расход электроэнергии/воды март 2024г.
B28: Местоположение: | E28: М11 магазин "Пчелка маркет" г. Киев, Автозаводська,27
B30: № п/п | C30: Название потребителя | D30: Юридическое лицо | E30: № счетчика | F30: Энергоноситель | G30: Показатели счетчика | K30: Коэф. | L30: Потребление, кВт/ч, м3/ч | M30: Стоимость 1кВт/ч, м3/ч | N30: Итого
G31: Дата снятия | H31: Показатели | I31: Дата снятия | J31: Показатели
B32: 1 | C32: ФОП ЧАХОЯН ГАЙК ЕДВАРДОВИЧ | E32: (ТП) NIK 2303 ARP1 №0198983 | F32: Активня э.э. | G32: 31.02.2024 | H32: 310.53 | I32: 45381 | J32: 346.33 | K32: 30 | L32: =J32-H32 -> 35.8 | M32: 5.014 | N32: =M32*L32*K32 -> 5385.036
M33: ИТОГО: | N33: =SUM(N32) -> 5385.036 | O33: грн.
B34: Расход электроэнергии/воды за квітень 2024г.
B35: Местоположение: | E35: М11 магазин "Пчелка маркет" г. Киев, Автозаводська,27
B37: № п/п | C37: Название потребителя | D37: Юридическое лицо | E37: № счетчика | F37: Энергоноситель | G37: Показатели счетчика | K37: Коэф. | L37: Потребление, кВт/ч, м3/ч | M37: Стоимость 1кВт/ч, м3/ч | N37: Итого
G38: Дата снятия | H38: Показатели | I38: Дата снятия | J38: Показатели
B39: 1 | C39: ФОП ЧАХОЯН ГАЙК ЕДВАРДОВИЧ | E39: (ТП) NIK 2303 ARP1 №0198983 | F39: Активня э.э. | G39: 45382 | H39: 346.33 | I39: 31.04.2024 | J39: 354.45 | K39: 30 | L39: =J39-H39 -> 8.12 | M39: 5.551212 | N39: =M39*L39*K39 -> 1352.2752
M40: ИТОГО: | N40: =SUM(N39) -> 1352.2752 | O40: грн.
B42: Расход электроэнергии/воды май 2024г.
B43: Местоположение: | E43: М11 магазин "Пчелка маркет" г. Киев, Автозаводська,27
B45: № п/п | C45: Название потребителя | D45: Юридическое лицо | E45: № счетчика | F45: Энергоноситель | G45: Показатели счетчика | K45: Коэф. | L45: Потребление, кВт/ч, м3/ч | M45: Стоимость 1кВт/ч, м3/ч | N45: Итого
G46: Дата снятия | H46: Показатели | I46: Дата снятия | J46: Показатели
B47: 1 | C47: ФОП ЧАХОЯН ГАЙК ЕДВАРДОВИЧ | E47: (ТП) NIK 2303 ARP1 №0198983 | F47: Активня э.э. | G47: 31.04.2024 | H47: 354.45 | I47: 45442 | J47: 361.46 | K47: 30 | L47: =J47-H47 -> 7.01 | M47: 6.5632799 | N47: =M47*L47*K47 -> 1380.2578
M48: ИТОГО: | N48: =SUM(N47) -> 1380.2578 | O48: грн.
B49: Расход электроэнергии/воды июнь 2024г.
B50: Местоположение: | E50: М11 магазин "Пчелка маркет" г. Киев, Автозаводська,27
B52: № п/п | C52: Название потребителя | D52: Юридическое лицо | E52: № счетчика | F52: Энергоноситель | G52: Показатели счетчика | K52: Коэф. | L52: Потребление, кВт/ч, м3/ч | M52: Стоимость 1кВт/ч, м3/ч | N52: Итого
G53: Дата снятия | H53: Показатели | I53: Дата снятия | J53: Показатели
...

Sheet М40
B3: Расход электроэнергии/воды за ЛЮТИЙ 2024г.
B4: Местоположение: | E4: М40 магазин "Пчелка маркет"Б.Церковь. Ул. Метрофанова,8
B6: № п/п | C6: Название потребителя | D6: Юридическое лицо | E6: № счетчика | F6: Энергоноситель | G6: Показатели счетчика | K6: Коэф. | L6: Потребление, кВт/ч, м3/ч | M6: Стоимость 1кВт/ч, м3/ч | N6: Итого
G7: Дата снятия | H7: Показатели | I7: Дата снятия | J7: Показатели
B8: 1 | C8: РЕНТ ЛАЙН КОМПАНІ | D8: ТОВ КИЕВСКИЙ ТРЕЙД | E8: №0075071140 | F8: Активня э.э. | G8: 44592 | H8: 34363 | I8: 45351 | J8: 34984 | K8: 1 | L8: =J8-H8 -> 621 | M8: 6.737708 | N8: =M8*L8*K8 -> 4184.1167
B9: 3 | D9: АТЛАНТ СПОРТ | E9: NIK2300 №20375257 | F9: Активня э.э. | G9: 44592 | H9: 1186 | I9: 45351 | J9: 1212 | K9: 1 | L9: =J9-H9 -> 26 | M9: =M8 -> 6.737708 | N9: =M9*L9*K9 -> 175.18041
M10: ИТОГО: | N10: =SUM(N8:N9) -> 4359.2971 | O10: грн.
B11: Расход электроэнергии/воды за березень 2024г.
B12: Местоположение: | E12: М40 магазин "Пчелка маркет"Б.Церковь. Ул. Метрофанова,8
B14: № п/п | C14: Название потребителя | D14: Юридическое лицо | E14: № счетчика | F14: Энергоноситель | G14: Показатели счетчика | K14: Коэф. | L14: Потребление, кВт/ч, м3/ч | M14: Стоимость 1кВт/ч, м3/ч | N14: Итого
G15: Дата снятия | H15: Показатели | I15: Дата снятия | J15: Показатели
B16: 1 | C16: РЕНТ ЛАЙН КОМПАНІ | D16: ТОВ КИЕВСКИЙ ТРЕЙД | E16: №0075071140 | F16: Активня э.э. | G16: 45351 | H16: 34984 | I16: 45382 | J16: 35672 | K16: 1 | L16: =J16-H16 -> 688 | M16: 6.4699321 | N16: =M16*L16*K16 -> 4451.3133
B17: 3 | D17: АТЛАНТ СПОРТ | E17: NIK2300 №20375257 | F17: Активня э.э. | G17: 45351 | H17: 79.52 | I17: 45382 | J17: 149 | K17: 40 | L17: =J17-H17 -> 69.48 | M17: =M16 -> 6.4699321 | N17: =M17*L17*K17 -> 17981.235
M18: ИТОГО: | N18: 22432.548 | O18: грн.
B20: Расход электроэнергии/воды за квітень 2024г.
B21: Местоположение: | E21: М40 магазин "Пчелка маркет"Б.Церковь. Ул. Метрофанова,8
B23: № п/п | C23: Название потребителя | D23: Юридическое лицо | E23: № счетчика | F23: Энергоноситель | G23: Показатели счетчика | K23: Коэф. | L23: Потребление, кВт/ч, м3/ч | M23: Стоимость 1кВт/ч, м3/ч | N23: Итого
G24: Дата снятия | H24: Показатели | I24: Дата снятия | J24: Показатели
B25: 1 | C25: РЕНТ ЛАЙН КОМПАНІ | D25: ТОВ КИЕВСКИЙ ТРЕЙД | E25: №0075071140 | F25: Активня э.э. | G25: 45382 | H25: 35672 | I25: 45412 | J25: 36216 | K25: 1 | L25: =J25-H25 -> 544 | M25: 6.737708 | N25: =M25*L25*K25 -> 3665.3131
B26: 3 | D26: АТЛАНТ СПОРТ | E26: NIK2300 №20375257 | F26: Активня э.э. | G26: 45382 | H26: 149 | I26: 45412 | J26: 195.19 | K26: 40 | L26: =J26-H26 -> 46.19 | M26: =M25 -> 6.737708 | N26: =M26*L26*K26 -> 12448.589
M27: ИТОГО: | N27: 22432.548 | O27: грн.
B28: Расход электроэнергии/воды за травень 2024г.
B29: Местоположение: | E29: М40 магазин "Пчелка маркет"Б.Церковь. Ул. Метрофанова,8
B31: № п/п | C31: Название потребителя | D31: Юридическое лицо | E31: № счетчика | F31: Энергоноситель | G31: Показатели счетчика | K31: Коэф. | L31: Потребление, кВт/ч, м3/ч | M31: Стоимость 1кВт/ч, м3/ч | N31: Итого
G32: Дата снятия | H32: Показатели | I32: Дата снятия | J32: Показатели
B33: 1 | C33: РЕНТ ЛАЙН КОМПАНІ | D33: ТОВ КИЕВСКИЙ ТРЕЙД | E33: №0075071140 | F33: Активня э.э. | G33: 45412 | H33: 36216 | I33: 45442 | J33: 36694 | K33: 1 | L33: =J33-H33 -> 478 | M33: 7.6846319 | N33: =M33*L33*K33 -> 3673.2541 | Q33: 36980
B34: 3 | D34: АТЛАНТ СПОРТ | E34: NIK2300 №20375257 | F34: Активня э.э. | G34: 45412 | H34: 195.19 | I34: 45442 | J34: 256.69 | K34: 40 | L34: =J34-H34 -> 61.5 | M34: =M33 -> 7.6846319 | N34: =M34*L34*K34 -> 18904.195
M35: ИТОГО: | N35: 22432.548
B37: Расход электроэнергии/воды за червень 2024г.
B38: Местоположение: | E38: М40 магазин "Пчелка маркет". Б.Церковь, ул. Митрофанова,8
B40: № п/п | C40: Название потребителя | D40: Юридическое лицо | E40: № счетчика | F40: Энергоноситель | G40: Показатели счетчика | K40: Коэф. | L40: Потребление, кВт/ч, м3/ч | M40: Стоимость 1кВт/ч, м3/ч | N40: Итого
G41: Дата снятия | H41: Показатели | I41: Дата снятия | J41: Показатели
B42: 1 | C42: РЕНТ ЛАЙН КОМПАНІ | D42: ТОВ КИЕВСКИЙ ТРЕЙД | E42: №0075071140 | F42: Активня э.э. | G42: 45442 | H42: 36694 | I42: 45473 | J42: 36980 | K42: 1 | L42: =J42-H42 -> 286 | M42: 8.6037359 | N42: =M42*L42*K42 -> 2460.6685
D43: АТЛАНТ СПОРТ | E43: NIK2300 №20375257 | F43: Активня э.э. | G43: 45442 | H43: 256.69 | I43: 45473 | J43: 325.22 | K43: 40 | L43: =J43-H43 -> 68.53 | M43: =M42 -> 8.6037359 | N43: =M43*L43*K43 -> 23584.561
F44: вода | G44: 45443 | H44: 1298 | I44: 45473 | J44: 1323 | L44: =J44-H44 -> 25
M45: ИТОГО: | N45: =SUM(N42:N44) -> 26045.229
B47: Расход электроэнергии/воды за липень 2024г.
B48: Местоположение: | E48: М40 магазин "Пчелка маркет". Б.Церковь, ул. Митрофанова,8
B50: № п/п | C50: Название потребителя | D50: Юридическое лицо | E50: № счетчика | F50: Энергоноситель | G50: Показатели счетчика | K50: Коэф. | L50: Потребление, кВт/ч, м3/ч | M50: Стоимость 1кВт/ч, м3/ч | N50: Итого
G51: Дата снятия | H51: Показатели | I51: Дата снятия | J51: Показатели
...
