Workbook

Sheet Договора
B2: ФОП Бондарчук В.В. Киевводоканал | C2: о/р 7-2776 | D2: М22 | E2: Договор №10896/5-10СА від 16.11.2018р.
B3: ФОП Ковальова Л.В. Киевводоканал | C3: о/р 8-1833 | D3: М5 | E3: Договор №03789/5-09СА від 04.04.2016р.
B4: ФОП Тришапко С.Д. Киевводоканал | C4: о/р 5-1374 | D4: М10 | E4: договор №10890/5-05 від 20.11.2012р.
B5: Логин Киевводоканал (М15) | C5: 39775097 | D5: пароль | E5: Legion2015
A6: Логин | B6: Киевэнерго ЛЕГИОН 2015 М3-ул.Р.Окипной,3 ; М5-ул.Я.Коласа, 2А; М6-ул. Сикорского,1А; М10- ул.Героев Сталинграда,65Б; М12 - ул.Антоновича,115Д; М15-ул.Шолом-Алейхема, 10а; М20-ул. Бориспольская, 32А, М22-ул. Ветряные горы, 21/7; М37-пр.Воздухофлотский, 19/1-А | C6: 43305015 | D6: пароль | E6: Legion2015 (Pass11!!)
A7: РИДО | B7: ДТЕК КИЇВСКИЕ СЕТИ М26,М11 | C7: 54299019 | D7: пароль | E7: Legion2015 (Pass11!!)
A8: Логин | B8: ТОЛК Україна М1/1;М8;М21;М34;М43;М25 | C8: №10-000217
A9: РИДО | B9: ТОЛК Україна М24;М40;М41;М17/1 | C9: №10-000218
A10: ЛЕГІОН | B10: АТ"ЖИТОМЕРОБЛЕНЕРГО" ЖИТОМИРСЬКИЙ РЕМ М1/1 г.Житомир. Пр.Мира,15 | C10: 762-РЕ
A11: ЛЕГІОН | B11: ДТЕК КИЇВСЬКІ РЕГІОНАЛЬНІ МЕРЕЖІ М8г.Ирпень, 10-я линия,1Б ; М21'г.Ирпень, ул. Тургеневская, 50б | C11: 220077408 | D11: пароль | E11: Legion2015
A12: ЛЕГІОН | B12: ДТЕК КИЇВСЬКІ РЕГІОНАЛЬНІ МЕРЕЖІ (М34) п.г.т. Софиевская Борщаговка, ул. Соборная 105/7 | C12: 220102339
A13: ЛЕГІОН | B13: ДТЕК КИЇВСЬКІ РЕГІОНАЛЬНІ МЕРЕЖІ М43 Боярка ул.Бульварная2/50) М25 'с.С.Борщаговка, ул. П.Чубинского, 8в | C13: 220105913
A14: РІДО | B14: ДТЕК КИЇВСЬКІ РЕГІОНАЛЬНІ МЕРЕЖІ 'М24 с.Глеваха, ул. Ботаническая, 34 ТП 566 | C14: 220090824
A15: РІДО | B15: ДТЕК КИЇВСЬКІ РЕГІОНАЛЬНІ МЕРЕЖІ М40'Б.Церковь. Ул. Метрофанова,8 М41'Б.Церковь. Ул. Сквирское шоссе, 223 /223 -А | C15: 220104936
A16: РІДО | B16: ДТЕК КИЇВСЬКІ РЕГІОНАЛЬНІ МЕРЕЖІ М17/1 'Борисполь, Головатого 64 | C16: 220105089
B31: Логин Киевская областная ЕК (М8М21) | C31: 420077408 | D31: пароль | E31: Legion2015
B32: Логин Киевская областная ЕК (М8М21) | C32: 420077408
B33: Логин ДТЕК КИЇВСЬКІ РЕГІОНАЛЬНІ МЕРЕЖІ(М8 М21)
B34: Логин Киевская областная ЕК (М28) | C34: 420084292 | D34: пароль | E34: RidoGroup
B35: Логин Киевводоканал (М30) | C35: 2606413815 | D35: пароль | E35: Legion2015
B43: Логин Киевоблэнерго (М28) | C43: 220083760 | D43: пароль | E43: RidoGroup

Sheet Потужнісьть
C2: НАЗВАНИЕ ОБЪЕКТА | E2: АДРЕС ОБЪЕКТА | H2: ЮРИДИЧЕСКОЕ (ФИЗИЧЕСКОЕ) ЛИЦО | K2: НАИМЕНОВАНИЕ | M2: Предыдущий период | O2: Тариф | P2: август | U2: Мощность по договору | V2: Потужність Холодильних установок | BD2: Дата счета | BH2: Срок оплаты | BM2: Предыдущий период | BY2: Тариф | CC2: АВГУСТ 2021г.
M3: Показатели | N3: Сумма | P3: Показатели | Q3: Сумма | R3: Авансы | S3: Реально | T3: Бюджет | BM3: Показатели | BS3: Сумма | CC3: Показатели | CI3: Сумма | CO3: Аренда | CT3: Реально | DB3: Бюджет
C5: Магазин М1/1 "Пчелка маркет" | E5: г.Житомир, пр. Мира, 15 | H5: ТОВ ГРІН БІН Україна | K5: Вывоз ТБО | Q5: 100 | S5: =Q9+Q8+Q6+Q5+R7 -> 203696.56 | T5: 80000 | U5: 128,3 кВт/ч
K6: Экспл. расходы
H7: ООО «Житомирская областная энергетическая компания» | K7: Активная ЭЭ | O7: =Q7/P7 -> 5.6305558 | P7: 45596 | Q7: 256730.82 | R7: 200000
H8: ООО «Житомиробленерго», АТ "Житомиробленерго" Житомирський РЕМ | K8: Реактивная ЭЭ | P8: 1 | Q8: 1395.94
H9: КП "Житомирводоканал" | K9: ХВ | O9: =Q9/P9 -> 37.941724 | P9: 58 | Q9: 2200.62
C10: Магазин М2 "Пчелка маркет" | E10: г.Киев, ул.Владимирская, 73/77 | H10: ТОВ "Еко-Грінко" | K10: Вывоз ТБО | P10: =H719 -> 2 | Q10: =J719 -> 382.8 | S10: =SUM(Q10:Q14) -> 68703.216 | U10: 43 кВт/ч
H11: ІП "Альфа Консалтінг" | K11: Экспл. расходы | P11: 1 | Q11: =1.2*2899.56 -> 3479.472
K12: Активная ЭЭ | O12: =Q12/P12 -> 4.7490724 | P12: 13461 | Q12: =1.2*53272.72 -> 63927.264
K13: Реактивная ЭЭ | P13: 1 | Q13: =1.2*663.67 -> 796.404
K14: ХВ | O14: =Q14/P14 -> 30.382383 | P14: 3.86 | Q14: =1.2*97.73 -> 117.276
C15: Магазин М3 "Пчелка маркет" | E15: г.Киев, ул.Р.Окипной,3 | H15: ТОВ "Еко-Грінко" | K15: Вывоз ТБО | P15: =H720 -> 6 | Q15: =J720 -> 1148.4 | S15: =SUM(Q15:Q18) -> 97694.364 | T15: 110000 | U15: 100 кВт/ч
H16: ТОВ "Київські електричні мережи" | K16: Активная ЭЭ | O16: =Q16/P16 -> 4.6710718 | P16: 20044 | Q16: =1.2*78022.47 -> 93626.964
H17: ДТЕК "Київські електричні мережі" | K17: Реактивная ЭЭ | Q17: 889.96
H18: ФОП Воробьев А.Н. | K18: ХВ | O18: =Q18/P18 -> 32.206984 | P18: 63 | Q18: 2029.04
C19: Магазин М4/1 "Пчелка маркет" | E19: пгт.Коцюбинское, ул. Пономарева, 28а | H19: ПП "Обухівміськвторресурси" | K19: Вывоз ТБО | P19: =Q718 -> 9 | Q19: =S718 -> 1980 | S19: =SUM(Q19:Q22)+N20 -> 91127.866 | T19: 103000 | U19: 50 кВт/ч
H20: НВПФ "Казі-2" | K20: Активная ЭЭ | O20: =Q20/P20 -> 5.2324438 | P20: 15954 | Q20: =1.2*69565.34 -> 83478.408
K21: Реактивная ЭЭ | P21: 1 | Q21: =1.2*2692.49 -> 3230.988
K22: ХВ | O22: =Q22/P22 -> 35.859853 | P22: 68 | Q22: 2438.47
C23: Магазин М5 "Пчелка маркет" | E23: г.Киев, ул. Я.Колоса,2А | H23: ТОВ "Еко-Грінко" | K23: Вывоз ТБО | P23: =H717 -> 8 | Q23: =J717 -> 1531.2 | S23: =SUM(Q23:Q26) -> 90074.364 | T23: 90000 | U23: 84,3 кВт/ч (не меньше 70
H24: ТОВ "Київські електричні мережи" | K24: Активная ЭЭ | O24: =Q24/P24 -> 4.671072 | P24: 18633 | Q24: =1.2*72530.07 -> 87036.084
H25: ДТЕК "Київські електричні мережі" | K25: Реактивная ЭЭ | Q25: 837.26
H26: ФОП Ковальова Л.В. | K26: ХВ | O26: =Q26/P26 -> 30.446364 | P26: 22 | Q26: 669.82
C27: Магазин М6 "Пчелка маркет" | E27: г.Киев, ул. Сикорского,1А | H27: ТОВ "Еко-Грінко" | K27: Вывоз ТБО | P27: =H716 -> 27 | Q27: =J716 -> 5167.8 | S27: =SUM(Q27:Q32) -> 251503.33 | T27: 300000 | U27: 2*132,4 кВт
H28: ТОВ "Ковальська -Житлосервіс" | K28: Экспл. расходы | P28: 696.6 | Q28: 7280.87
P29: 465.4 | Q29: 4864.36
H30: ТОВ "Київські електричні мережи" | K30: Активная ЭЭ | O30: =Q30/P30 -> 4.6710719 | P30: 49263 | Q30: =1.2*191759.18 -> 230111.02
H31: ДТЕК "Київські електричні мережі" | K31: Реактивная ЭЭ | Q31: 2187.28
H32: ФОП Пластун В.В. | K32: ХВ | O32: =Q32/P32 -> 1892 | P32: 1 | Q32: 1892
C33: Магазин М7 "Пчелка маркет" | E33: г.Киев, ул. Коновальца,44Б | H33: ТОВ "Еко-Грінко" | K33: Вывоз ТБО | P33: =H721 -> 4 | Q33: =J721 -> 765.6 | S33: =SUM(Q33:Q39)+N36 -> 182338.56 | T33: 385000 | U33: 75 кВт/ч
H34: ТОВ "ОК "Комфорт" | K34: Экспл. расходы | P34: 1 | Q34: =17607.25+1534.43 -> 19141.68
K35: Реактивная ЭЭ | P35: 1 | Q35: =1.2*1463.16 -> 1755.792
K36: Активная ЭЭ | O36: =Q36/P36 -> 4.5406559 | P36: 31980 | Q36: =1.2*121008.48 -> 145210.18
K37: Обслуживание сетей | P37: 1 | Q37: =1.2*(8573.01+3674.15+40.77+17.47) -> 14766.48
K38: Тепловая энергия | P38: 0.41
K39: ХВ | P39: 23 | Q39: =1.2*(309.81+272.55) -> 698.832
C40: Магазин М8 "Пчелка маркет" | E40: г.Ирпень, 10-я линия,1Б | H40: ПП "Обухівміськвторресурси" | K40: Вывоз ТБО | O40: =Q40/P40 -> #DIV/0! | P40: =Q717 -> 0 | Q40: =S717 -> 0 | S40: =SUM(Q40:Q44)+N40 -> 0 | T40: 255000 | U40: 140 кВт/ч (не меньше 105)
H41: ТОВ "ТЦ "Вайт Хауз" | K41: Экспл. расходы
H42: ТОВ "Київські електричні мережи" | K42: Активная ЭЭ | O42: =Q42/P42 -> #DIV/0!
...

Sheet ОПЛАТИ 2023
A1: НАЗВАНИЕ ОБЪЕКТА | B1: АДРЕС ОБЪЕКТА | C1: ЮРИДИЧЕСКОЕ (ФИЗИЧЕСКОЕ) ЛИЦО | D1: НАИМЕНОВАНИЕ | E1: Столбец1 | F1: Тариф | G1: Показатели | H1: Сумма | I1: Авансы | J1: грудень 2022 | K1: Тариф | L1: Показатели | M1: Сумма | N1: Авансы | O1: січень 2023 | P1: Тариф | Q1: Показатели | R1: Сумма | S1: Авансы | T1: лютий 2023 | U1: Тариф | V1: Показатели | W1: Сумма | X1: Авансы | Y1: березень 2023 | Z1: Тариф | AA1: Показатели | AB1: Сумма | AC1: Авансы | AD1: квітень 2023 | AE1: Тариф | AF1: Показатели | AG1: Сумма | AH1: Авансы | AI1: травень 2023 | AJ1: Тариф | AK1: Показатели | AL1: Сумма | AM1: Авансы | AN1: червень 2023 | AO1: Тариф | AP1: Показатели | AQ1: Сумма | AR1: Авансы | AS1: Липень 2023 | AT1: Тариф | AU1: Показатели | AV1: Сумма | AW1: Авансы | AX1: Серпень 2023 | AY1: Тариф | AZ1: Показатели | BA1: Сумма | BB1: Авансы | BC1: Вересень 2023 | BD1: Тариф | BE1: Показатели | BF1: Сумма | BG1: Авансы | BH1: Жовтень 2023 | BI1: Тариф | BJ1: Показатели | BK1: Сумма | BL1: Авансы | BM1: Листопад 2023 | BN1: Тариф | BO1: Показатели | BP1: Сумма | BQ1: Авансы | BR1: Грудень 2023 | BS1: Тариф | BT1: Показатели | BU1: Сумма | BV1: Авансы | BW1: Січень 2024 | BX1: Тариф | BY1: Показатели | BZ1: Сумма | CA1: Авансы | CB1: Лютий 2024 | CC1: Тариф | CD1: Показатели | CE1: Сумма | CF1: Авансы | CG1: Березень 2024 | CH1: Тариф | CI1: Показатели | CJ1: Сумма | CK1: Авансы | CL1: Квітень 2024 | CM1: Тариф | CN1: Показатели | CO1: Сумма | CP1: Авансы | CQ1: Травень 2024 | CR1: Тариф | CS1: Показатели | CT1: Сумма | CU1: Авансы | CV1: червень 2024 | CW1: Тариф | CX1: Показатели | CY1: Сумма | CZ1: Авансы | DA1: Липень 2024
A3: М1/1 | B3: г.Житомир, пр. Мира, 15 | C3: ТОВ ГРІН БІН Україна | D3: Вывоз ТБО | W3: 2 913,33 | Y3: =SUM(W3:W7)*1.1 -> 266598.77 | Z3: 330000 | AB3: 100 | AD3: =SUM(AB3:AB7)*1.1 -> 254435.93 | AG3: =3277.5+600 -> 3877.5 | AI3: =AI4*1.1 -> 304938.28 | AL3: 100 | AN3: =AN4*1.2 -> 244056.49 | AQ3: 100 | AS3: =SUM(AQ3:AQ7)*1.3 -> 417523.31 | AV3: 100 | AX3: =SUM(AV3:AV7)*1 -> 339604.38 | BA3: 100 | BC3: =SUM(BA3:BA7)*1.11 -> 341852.35 | BF3: 100 | BH3: =SUM(BF3:BF7)*1.1 -> 326765.93 | BK3: 100 | BM3: =SUM(BK3:BK7)*1.1 -> 373177.56 | BP3: 100 | BR3: =SUM(BP3:BP7)*1.1 -> 407182.36 | BU3: 100 | BW3: =SUM(BU3:BU7)*1.1 -> 385830.64 | BZ3: 100 | CB3: =SUM(BZ3:BZ7)*1.1 -> 266185.5 | CE3: 100 | CG3: =SUM(CE3:CE7)*1.1 -> 266185.5 | CJ3: 100 | CL3: =SUM(CJ3:CJ7)*1.1 -> 266185.5 | CO3: 100 | CQ3: =SUM(CO3:CO7)*1.1 -> 266185.5 | CT3: 100 | CV3: =SUM(CT3:CT7)*1.1 -> 266185.5 | CY3: 100 | DA3: =SUM(CY3:CY7)*1.1 -> 266185.5
D4: Экспл. расходы | Y4: =SUM(W3:W7)*1 -> 242362.52 | AD4: =SUM(AB3:AB7)*1 -> 231305.39 | AI4: =SUM(AG6:AG7)+AH5+AG3*1 -> 277216.62 | AN4: =SUM(AL6:AL7)+AM5+AL3*1 -> 203380.41 | AS4: =SUM(AQ3:AQ7)*1 -> 321171.78 | AX4: =SUM(AV3:AV7)*1 -> 339604.38 | BC4: =SUM(BA7+BA6+BA3+BB5) -> 334718.35 | BH4: =SUM(BF3:BF7)*1 -> 297059.94 | BM4: =SUM(BK3:BK7)*1 -> 339252.33 | BR4: =SUM(BP3:BP7)*1 -> 370165.78 | BW4: =SUM(BU7+BU6+BV5+BU3)*1 -> 401619.69 | CB4: =SUM(BZ3:BZ7)*1 -> 241986.82 | CG4: =SUM(CE3:CE7)*1 -> 241986.82 | CL4: =SUM(CJ3:CJ7)*1 -> 241986.82 | CQ4: =SUM(CO3:CO7)*1 -> 241986.82 | CV4: =SUM(CT3:CT7)*1 -> 241986.82 | DA4: =SUM(CY3:CY7)*1 -> 241986.82
B5: 42095943 | C5: ООО «Житомирская областная энергетическая компания» | D5: Активная ЭЭ | F5: =H5/G5 -> 6.2021216 | G5: 38462 | H5: 238546 | I5: 270000 | K5: =M5/L5 -> 6.444444 | L5: 49797 | M5: 320913.98 | N5: 270000 | P5: =R5/Q5 -> 6.0761997 | Q5: 40623 | R5: 246833.46 | S5: 325000 | U5: =W5/V5 -> 5.1846598 | V5: 46075 | W5: 238883.2 | X5: 300000 | Z5: =AB5/AA5 -> 5.8564076 | AA5: 38871 | AB5: 227644.42 | AC5: 250000 | AE5: =AG5/AF5 -> 5.8430275 | AF5: 41718 | AG5: 243759.42 | AH5: 270000 | AJ5: =AL5/AK5 -> 5.9171158 | AK5: 41062 | AL5: 242968.61 | AM5: 200000 | AO5: =AQ5/AP5 -> 6.6963836 | AP5: 47425 | AQ5: 317575.99 | AR5: 270000 | AT5: =AV5/AU5 -> 7.303896 | AU5: 45886 | AV5: 335146.57 | AW5: =130588.31+399432.6 -> 530020.91 | AY5: =BA5/AZ5 -> 7.035096 | AZ5: 43220 | BA5: 304056.85 | BB5: 330800.11 | BD5: =BF5/BE5 -> 7.1411038 | BE5: 41329 | BF5: 295134.68 | BG5: 270000 | BI5: =BK5/BJ5 -> 7.4900641 | BJ5: 44771 | BK5: 335337.66 | BL5: 270000 | BN5: =BP5/BO5 -> 7.1331721 | BO5: 51550 | BP5: 367715.02 | BQ5: 300000 | BS5: =BU5/BT5 -> 7.067688 | BT5: 48971 | BU5: 346111.75 | BV5: 396976.31 | BX5: =BZ5/BY5 -> 6.2021216 | BY5: 38462 | BZ5: 238546 | CA5: 248322.31 | CC5: =CE5/CD5 -> 6.2021216 | CD5: 38462 | CE5: 238546 | CH5: =CJ5/CI5 -> 6.2021216 | CI5: 38462 | CJ5: 238546 | CM5: =CO5/CN5 -> 6.2021216 | CN5: 38462 | CO5: 238546 | CR5: =CT5/CS5 -> 6.2021216 | CS5: 38462 | CT5: 238546 | CW5: =CY5/CX5 -> 6.2021216 | CX5: 38462 | CY5: 238546
B6: 22048622 | C6: ООО «Житомиробленерго», АТ "Житомиробленерго" Житомирський РЕМ | D6: Реактивная ЭЭ | G6: 1 | H6: 990.06 | L6: 1 | M6: 1198.26 | Q6: 1 | R6: 1065.68 | V6: 1 | W6: 1278.7 | AA6: 1 | AB6: 1135.13 | AF6: 1 | AG6: 1251.11 | AK6: 1 | AL6: 1342.54 | AP6: 1 | AQ6: 1595.46 | AU6: 1 | AV6: 1894.44 | AZ6: 1 | BA6: 2030.52 | BE6: 1 | BF6: 1 545,68 | BJ6: 1 | BK6: 1 687,28 | BO6: 1 | BP6: 1 830,90 | BT6: 1 | BU6: 1742.18 | BY6: 1 | BZ6: 990.06 | CD6: 1 | CE6: 990.06 | CI6: 1 | CJ6: 990.06 | CN6: 1 | CO6: 990.06 | CS6: 1 | CT6: 990.06 | CX6: 1 | CY6: 990.06
B7: 03344065 | C7: КП "Житомирводоканал" | D7: ХВ | F7: 37.536 | G7: =Таблица3[[#This Row],[Сумма]]/Таблица3[[#This Row],[Тариф]] -> 59.627025 | H7: 2238.16 | K7: =M7/L7 -> 37.928167 | L7: 60 | M7: 2275.69 | P7: =R7/Q7 -> 37.928167 | Q7: 60 | R7: 2275.69 | U7: =W7/V7 -> 37.941724 | V7: 58 | W7: 2200.62 | Z7: =AB7/AA7 -> 37.90375 | AA7: 64 | AB7: 2425.84 | AE7: =AG7/AF7 -> 37.963818 | AF7: 55 | AG7: 2088.01 | AJ7: =AL7/AK7 -> 37.997451 | AK7: 51 | AL7: 1937.87 | AO7: =AQ7/AP7 -> 38.0066 | AP7: 50 | AQ7: 1900.33 | AT7: =AV7/AU7 -> 37.898 | AU7: 65 | AV7: 2463.37 | AY7: =BA7/AZ7 -> 38.036596 | AZ7: 47 | BA7: 1787.72 | BD7: =BF7/BE7 -> 38.02625 | BE7: 48 | BF7: =1825.26 -> 1825.26 | BG7: 192.61 | BI7: =BK7/BJ7 -> 37.76901 | BJ7: 101 | BK7: 3814.67 | BN7: =BP7/BO7 -> 37.915484 | BO7: 62 | BP7: 2350.76 | BS7: =BU7/BT7 -> 37.854054 | BT7: 74 | BU7: 2801.2 | BX7: =BZ7/BY7 -> 37.915484 | BY7: 62 | BZ7: 2350.76 | CC7: =CE7/CD7 -> 37.915484 | CD7: 62 | CE7: 2350.76 | CH7: =CJ7/CI7 -> 37.915484 | CI7: 62 | CJ7: 2350.76 | CM7: =CO7/CN7 -> 37.915484 | CN7: 62 | CO7: 2350.76 | CR7: =CT7/CS7 -> 37.915484 | CS7: 62 | CT7: 2350.76 | CW7: =CY7/CX7 -> 37.915484 | CX7: 62 | CY7: 2350.76
A8: М2 | B8: г.Киев, ул.Владимирская, 73/77 | C8: ТОВ "Еко-Грінко" | D8: Вывоз ТБО | W8: 1990 | Y8: =SUM(W8:W12)*1.1 -> 64870.718 | AB8: 1548 | AD8: =SUM(AB8:AB12)*1.1 -> 49751.473 | AG8: 1920 | AI8: =AI9*1.1 -> 64838.783 | AL8: 1990 | AN8: =AN9*1.2 -> 82628.328 | AQ8: 1769 | AS8: =SUM(AQ8:AQ12)*1.2 -> 101644.94 | AX8: =SUM(AV8:AV12)*1.1 -> 106741.39 | BC8: =SUM(BA8:BA12)*1.22 -> 106425.64 | BH8: =SUM(BF8:BF12)*1.1 -> 68123.642 | BM8: =SUM(BK8:BK12)*1.1 -> 104238.5 | BR8: =SUM(BP8:BP12)*1.1 -> 74189.056 | BW8: =SUM(BU8:BU12)*1.1 -> 23640.773 | CB8: =SUM(BZ8:BZ12)*1.1 -> 41354.412 | CG8: =SUM(CE8:CE12)*1.1 -> 41354.412 | CL8: =SUM(CJ8:CJ12)*1.1 -> 41354.412 | CQ8: =SUM(CO8:CO12)*1.1 -> 41354.412 | CV8: =SUM(CT8:CT12)*1.1 -> 41354.412 | DA8: =SUM(CY8:CY12)*1.1 -> 41354.412
B9: 35791356 | C9: ІП "Альфа Консалтінг" | D9: Экспл. расходы | G9: 1 | H9: =1.2*2899.56 -> 3479.472 | L9: 1 | M9: =1.2*2899.56 -> 3479.472 | Q9: 1 | R9: =1.2*2899.56 -> 3479.472 | V9: 1 | W9: =1.2*2899.56 -> 3479.472 | Y9: =SUM(W8:W12)*1 -> 58973.38 | AA9: 1 | AB9: =1.2*2899.56 -> 3479.472 | AD9: =SUM(AB8:AB12)*1 -> 45228.612 | AF9: 1 | AG9: =1.2*2899.56 -> 3479.472 | AI9: =SUM(AG8:AG12)*1 -> 58944.348 | AK9: 1 | AL9: =1.2*2899.56 -> 3479.472 | AN9: =SUM(AL8:AL12)*1 -> 68856.94 | AP9: 1 | AQ9: =1.2*2899.56 -> 3479.472 | AS9: =SUM(AQ8:AQ12)*1 -> 84704.12 | AU9: 1 | AV9: =1.2*2899.56 -> 3479.472 | AX9: =SUM(AV8:AV12)*1 -> 97037.628 | AZ9: 1 | BA9: =1.2*2899.56 -> 3479.472 | BC9: =SUM(BA8:BA12)*1 -> 87234.132 | BE9: 1 | BF9: =1.2*2899.56 -> 3479.472 | BH9: =SUM(BF8:BF12)*1 -> 61930.584 | BJ9: 1 | BK9: =1.2*2899.56 -> 3479.472 | BM9: =SUM(BK8:BK12)*1 -> 94762.274 | BO9: 1 | BP9: =1.2*2899.56 -> 3479.472 | BR9: =SUM(BP8:BP12)*1 -> 67444.596 | BT9: 1 | BU9: =1.2*2899.56 -> 3479.472 | BW9: =SUM(BU8:BU12)*1 -> 21491.612 | BY9: 1 | BZ9: =1.2*2899.56 -> 3479.472 | CB9: =SUM(BZ8:BZ12)*1 -> 37594.92 | CD9: 1 | CE9: =1.2*2899.56 -> 3479.472 | CG9: =SUM(CE8:CE12)*1 -> 37594.92 | CI9: 1 | CJ9: =1.2*2899.56 -> 3479.472 | CL9: =SUM(CJ8:CJ12)*1 -> 37594.92 | CN9: 1 | CO9: =1.2*2899.56 -> 3479.472 | CQ9: =SUM(CO8:CO12)*1 -> 37594.92 | CS9: 1 | CT9: =1.2*2899.56 -> 3479.472 | CV9: =SUM(CT8:CT12)*1 -> 37594.92 | CX9: 1 | CY9: =1.2*2899.56 -> 3479.472 | DA9: =SUM(CY8:CY12)*1 -> 37594.92
A10: ЯСНО "КИЇВСЬКІ ЕНЕРГЕТИЧНІ ПОСЛУГИ" | D10: Активная ЭЭ | F10: =H10/G10 -> 5.2317113 | G10: 6442 | H10: =1.2*28085.57 -> 33702.684 | K10: =M10/L10 -> 5.2938113 | L10: 6837 | M10: =1.2*30161.49 -> 36193.788 | P10: =R10/Q10 -> 5.331312 | Q10: 6442 | R10: =1.2*28620.26 -> 34344.312 | U10: =W10/V10 -> 5.218872 | V10: 10149 | W10: =1.2*44138.61 -> 52966.332 | Z10: =AB10/AA10 -> 5.0483036 | AA10: 7840 | AB10: =1.2*32982.25 -> 39578.7 | AE10: =AG10/AF10 -> 4.8623883 | AF10: 10848 | AG10: =1.2*43955.99 -> 52747.188 | AJ10: =AL10/AK10 -> 5.2394158 | AK10: 11942 | AL10: =1.2*52140.92 -> 62569.104 | AO10: =AQ10/AP10 -> 5.6894517 | AP10: 13796 | AQ10: =1.2*65409.73 -> 78491.676 | AT10: =AV10/AU10 -> 6.5030284 | AU10: 14191 | AV10: =1.2*76903.73 -> 92284.476 | AY10: =BA10/AZ10 -> 6.4884477 | AZ10: 12732 | BA10: =1.2*68842.43 -> 82610.916 | BD10: =BF10/BE10 -> 6.7719605 | BE10: 8508 | BF10: =1.2*48013.2 -> 57615.84 | BI10: =BK10/BJ10 -> 6.9206276 | BJ10: 13066 | BK10: =1.2*75354.1 -> 90424.92 | BN10: =BP10/BO10 -> 7.0693802 | BO10: 8964 | BP10: =1.2*52808.27 -> 63369.924 | BS10: =BU10/BT10 -> 6.1674965 | BT10: 2868 | BU10: 17688.38 | BX10: =BZ10/BY10 -> 5.2317113 | BY10: 6442 | BZ10: =1.2*28085.57 -> 33702.684 | CC10: =CE10/CD10 -> 5.2317113 | CD10: 6442 | CE10: =1.2*28085.57 -> 33702.684 | CH10: =CJ10/CI10 -> 5.2317113 | CI10: 6442 | CJ10: =1.2*28085.57 -> 33702.684 | CM10: =CO10/CN10 -> 5.2317113 | CN10: 6442 | CO10: =1.2*28085.57 -> 33702.684 | CR10: =CT10/CS10 -> 5.2317113 | CS10: 6442 | CT10: =1.2*28085.57 -> 33702.684 | CW10: =CY10/CX10 -> 5.2317113 | CX10: 6442 | CY10: =1.2*28085.57 -> 33702.684
D11: Реактивная ЭЭ | G11: 1 | H11: =1.2*235.35 -> 282.42 | L11: 1 | M11: =1.2*282.36 -> 338.832 | Q11: 1 | R11: =1.2*334.73 -> 401.676 | V11: 1 | W11: =1.2*344.42 -> 413.304 | AA11: 1 | AB11: =1.2*407.54 -> 489.048 | AF11: 1 | AG11: =1.2*556.12 -> 667.344 | AK11: 1 | AL11: =1.2*570.81 -> 684.972 | AP11: 1 | AQ11: =1.2*735.2 -> 882.24 | AU11: 1 | AV11: =1.2*909.73 -> 1091.676 | AZ11: 1 | BA11: =1.2*920.46 -> 1104.552 | BE11: 1 | BF11: =1.2*582.38 -> 698.856 | BJ11: 1 | BK11: 818.69 | BO11: 1 | BP11: =1.2*384.84 -> 461.808 | BT11: 1 | BU11: =1.2*158.64 -> 190.368 | BY11: 1 | BZ11: =1.2*235.35 -> 282.42 | CD11: 1 | CE11: =1.2*235.35 -> 282.42 | CI11: 1 | CJ11: =1.2*235.35 -> 282.42 | CN11: 1 | CO11: =1.2*235.35 -> 282.42 | CS11: 1 | CT11: =1.2*235.35 -> 282.42 | CX11: 1 | CY11: =1.2*235.35 -> 282.42
D12: ХВ | F12: =H12/G12 -> 33.767876 | G12: 3.86 | H12: =1.2*108.62 -> 130.344 | K12: =M12/L12 -> 28.797927 | L12: 3.86 | M12: 111.16 | P12: =R12/Q12 -> 34.557513 | Q12: 3.86 | R12: =1.2*111.16 -> 133.392 | U12: =W12/V12 -> 32.194819 | V12: 3.86 | W12: =1.2*103.56 -> 124.272 | Z12: =AB12/AA12 -> 34.557513 | AA12: 3.86 | AB12: =1.2*111.16 -> 133.392 | AE12: =AG12/AF12 -> 34.665957 | AF12: 3.76 | AG12: =1.2*108.62 -> 130.344 | AJ12: =AL12/AK12 -> 43.029677 | AK12: 3.1 | AL12: =1.2*111.16 -> 133.392 | AO12: =AQ12/AP12 -> 21.174093 | AP12: 3.86 | AQ12: =1.2*68.11 -> 81.732 | AT12: =AV12/AU12 -> 47.151295 | AU12: 3.86 | AV12: =1.2*151.67 -> 182.004 | AY12: =BA12/AZ12 -> 10.153368 | AZ12: 3.86 | BA12: =1.2*32.66 -> 39.192 | BD12: =BF12/BE12 -> 35.340933 | BE12: 3.86 | BF12: =1.2*113.68 -> 136.416 | BI12: =BK12/BJ12 -> 39.192 | BJ12: 1 | BK12: =1.2*32.66 -> 39.192 | BN12: =BP12/BO12 -> 133.392 | BO12: 1 | BP12: =1.2*111.16 -> 133.392 | BS12: =BU12/BT12 -> 133.392 | BT12: 1 | BU12: =1.2*111.16 -> 133.392 | BX12: =BZ12/BY12 -> 2.1023226 | BY12: 62 | BZ12: =1.2*108.62 -> 130.344 | CC12: =CE12/CD12 -> 2.1023226 | CD12: 62 | CE12: =1.2*108.62 -> 130.344 | CH12: =CJ12/CI12 -> 2.1023226 | CI12: 62 | CJ12: =1.2*108.62 -> 130.344 | CM12: =CO12/CN12 -> 2.1023226 | CN12: 62 | CO12: =1.2*108.62 -> 130.344 | CR12: =CT12/CS12 -> 2.1023226 | CS12: 62 | CT12: =1.2*108.62 -> 130.344 | CW12: =CY12/CX12 -> 2.1023226 | CX12: 62 | CY12: =1.2*108.62 -> 130.344
A13: М3 | B13: г.Киев, ул.Р.Окипной,3 | C13: ТОВ "Еко-Грінко" | D13: Вывоз ТБО | W13: 1769 | Y13: =SUM(W13:W16)*1.1 -> 69137.352 | AB13: 1769 | AD13: =SUM(AB13:AB16)*1.1 -> 64896.55 | AG13: 2211 | AI13: =AI14*1.1 -> 119705.9 | AL13: 1327 | AN13: =AN14*1.2 -> 155518.7 | AQ13: 2211 | AS13: =SUM(AQ13:AQ16)*1.2 -> 142971.74 | AX13: =SUM(AV13:AV16)*1.1 -> 145006.85 | BC13: =SUM(BA14:BA16)*1.2 -> 139319.87 | BH13: =SUM(BF13:BF16)*1.1 -> 109403.84 | BM13: =SUM(BK13:BK16)*1.1 -> 104134.14 | BR13: =SUM(BP13:BP16)*1.1 -> 104482.36 | BW13: =SUM(BU13:BU16)*1.1 -> 104340.07 | CB13: =SUM(BZ13:BZ16)*1.1 -> 24808.887 | CG13: =SUM(CE13:CE16)*1.1 -> 24808.887 | CL13: =SUM(CJ13:CJ16)*1.1 -> 24808.887 | CQ13: =SUM(CO13:CO16)*1.1 -> 24808.887 | CV13: =SUM(CT13:CT16)*1.1 -> 24808.887 | DA13: =SUM(CY13:CY16)*1.1 -> 24808.887
B14: 41916045 | C14: ТОВ "КИЇВСЬКI ЕНЕРГЕТИЧНI ПОСЛУГИ" | D14: Активная ЭЭ | F14: =H14/G14 -> 5.3077205 | G14: 3964 | H14: 21039.804 | I14: 14610.975 | K14: =M14/L14 -> 5.3685484 | L14: 8176 | M14: 43893.252 | N14: 43893.252 | P14: =R14/Q14 -> 4.9663922 | Q14: 8292 | R14: =34317.77*1.2 -> 41181.324 | S14: 41181.324 | U14: =W14/V14 -> 5.2077241 | V14: 11220 | W14: 58430.664 | X14: 58430.664 | Y14: =SUM(W13:W16)*1 -> 62852.138 | Z14: =AB14/AA14 -> 4.6829517 | AA14: 11676 | AB14: 54678.144 | AC14: 54678.144 | AD14: =SUM(AB13:AB16)*1 -> 58996.864 | AE14: =AG14/AF14 -> 4.819944 | AF14: 15136 | AG14: 72954.672 | AH14: =28777.97+74729.76 -> 103507.73 | AI14: =SUM(AG15:AG16)+AH14+AG13*1 -> 108823.55 | AJ14: =AL14/AK14 -> 4.9792203 | AK14: 17160 | AL14: 85443.42 | AM14: =37070.31+89591.256 -> 126661.57 | AN14: =SUM(AL15:AL16)+AM14+AL13*1 -> 129598.92 | AO14: =AQ14/AP14 -> 5.9466958 | AP14: 19092 | AQ14: 113534.32 | AR14: 128035 | AS14: =SUM(AQ13:AQ16)*1 -> 119143.12 | AT14: =AV14/AU14 -> 6.610763 | AU14: 19372 | AV14: 128063.7 | AW14: 14610.975 | AX14: =SUM(AV13:AV16)*1 -> 131824.41 | AY14: =BA14/AZ14 -> 6.3494518 | AZ14: 17688 | BA14: 112309.1 | BB14: 93590.92 | BC14: =(BA16+BA15+BA14)*1 -> 116099.89 | BD14: =BF14/BE14 -> 6.2594404 | BE14: 15596 | BF14: 97622.232 | BG14: 93590.92 | BH14: =SUM(BF13:BF16)*1 -> 99458.032 | BI14: =BK14/BJ14 -> 6.7596598 | BJ14: 13676 | BK14: 92445.108 | BL14: 77284.27 | BM14: =SUM(BK13:BK16)*1 -> 94667.398 | BN14: =BP14/BO14 -> 6.4951202 | BO14: 14180 | BP14: 92100.804 | BQ14: 14610.975 | BR14: =SUM(BP13:BP16)*1 -> 94983.964 | BS14: =BU14/BT14 -> 6.131988 | BT14: 15024 | BU14: 92126.988 | BV14: 93423.62 | BW14: =SUM(BU16+BU15+BV14)*1 -> 96151.24 | BX14: =BZ14/BY14 -> 5.3077205 | BY14: 3964 | BZ14: 21039.804 | CA14: 125 064,66 | CB14: =SUM(BZ13:BZ16)*1 -> 22553.534 | CC14: =CE14/CD14 -> 5.3077205 | CD14: 3964 | CE14: 21039.804 | CF14: 14610.975 | CG14: =SUM(CE13:CE16)*1 -> 22553.534 | CH14: =CJ14/CI14 -> 5.3077205 | CI14: 3964 | CJ14: 21039.804 | CK14: 14610.975 | CL14: =SUM(CJ13:CJ16)*1 -> 22553.534 | CM14: =CO14/CN14 -> 5.3077205 | CN14: 3964 | CO14: 21039.804 | CP14: 14610.975 | CQ14: =SUM(CO13:CO16)*1 -> 22553.534 | CR14: =CT14/CS14 -> 5.3077205 | CS14: 3964 | CT14: 21039.804 | CU14: 14610.975 | CV14: =SUM(CT13:CT16)*1 -> 22553.534 | CW14: =CY14/CX14 -> 5.3077205 | CX14: 3964 | CY14: 21039.804 | CZ14: 14610.975 | DA14: =SUM(CY13:CY16)*1 -> 22553.534
B15: 41946011 | C15: «ДТЕК КИЇВСЬКІ ЕЛЕКТРОМЕРЕЖІ» | D15: Реактивная ЭЭ | G15: 0 | H15: 0 | L15: 0 | M15: 651.98 | Q15: 0 | R15: 650.05 | W15: 945.504 | AA15: 0 | AB15: 1068.2 | AF15: 0 | AG15: 1462.27 | AK15: 0 | AL15: 1 525,16 | AQ15: 1761.86 | AU15: 0 | AV15: 2053.74 | AZ15: 0 | BA15: 1954.99 | BE15: 0 | BF15: 1 476,04 | BJ15: 0 | BK15: 1 115,62 | BO15: 0 | BP15: 950.74 | BT15: 1 | BU15: 988.44 | BY15: 0 | BZ15: 0 | CD15: 0 | CE15: 0 | CI15: 0 | CJ15: 0 | CN15: 0 | CO15: 0 | CS15: 0 | CT15: 0 | CX15: 0 | CY15: 0
B16: 2978013090 | C16: ФОП Воробьев А.Н. | D16: ХВ | F16: =H16/G16 -> 32.207021 | G16: 47 | H16: 1513.73 | K16: =M16/L16 -> 32.207105 | L16: 38 | M16: 1223.87 | P16: =R16/Q16 -> 32.207347 | Q16: 49 | R16: 1578.16 | U16: =W16/V16 -> 32.206981 | V16: 53 | W16: 1706.97 | Z16: =AB16/AA16 -> 32.206957 | AA16: 46 | AB16: 1481.52 | AE16: =AG16/AF16 -> 32.206863 | AF16: 51 | AG16: 1642.55 | AJ16: =AL16/AK16 -> 32.207 | AK16: 50 | AL16: 1610.35 | AO16: =AQ16/AP16 -> 34.082083 | AP16: 48 | AQ16: 1635.94 | AT16: =AV16/AU16 -> 32.206981 | AU16: 53 | AV16: 1706.97 | AY16: =BA16/AZ16 -> 32.207018 | AZ16: 57 | BA16: 1835.8 | BD16: =BF16/BE16 -> 32.207018 | BE16: 57 | BF16: 1835.8 | BI16: =BK16/BJ16 -> 32.207101 | BJ16: 69 | BK16: 2222.29 | BN16: =BP16/BO16 -> 32.207 | BO16: 60 | BP16: 1932.42 | BS16: =BU16/BT16 -> 32.207037 | BT16: 54 | BU16: 1739.18 | BX16: =BZ16/BY16 -> 32.207021 | BY16: 47 | BZ16: 1513.73 | CC16: =CE16/CD16 -> 32.207021 | CD16: 47 | CE16: 1513.73 | CH16: =CJ16/CI16 -> 32.207021 | CI16: 47 | CJ16: 1513.73 | CM16: =CO16/CN16 -> 32.207021 | CN16: 47 | CO16: 1513.73 | CR16: =CT16/CS16 -> 32.207021 | CS16: 47 | CT16: 1513.73 | CW16: =CY16/CX16 -> 32.207021 | CX16: 47 | CY16: 1513.73
A17: М4/1 | B17: пгт.Коцюбинское, ул. Пономарева, 28а | C17: ПП "Обухівміськвторресурси" | D17: Вывоз ТБО | W17: 2530 | Y17: =SUM(W17:W20)*1.2 -> 83719.562 | AB17: 2024 | AD17: =SUM(AB17:AB20)*1.2 -> 97664.035 | AG17: 2024 | AI17: =AI18*1.1 -> 98364.73 | AL17: 2530 | AN17: =AN18*1.2 -> 120776.1 | AS17: =SUM(AQ17:AQ20)*1.2 -> 143589.86 | AX17: =SUM(AV17:AV20)*1.2 -> 168735.83 | BC17: =SUM(BA17:BA20)*1.2 -> 132970.68 | BH17: =SUM(BF17:BF20)*1.2 -> 145941.81 | BM17: =SUM(BK17:BK20)*1.1 -> 150848.56 | BR17: =SUM(BP17:BP20)*1.2 -> 139827.85 | BW17: =SUM(BU17:BU20)*1.2 -> 132846.63 | CB17: =SUM(BZ17:BZ20)*1.2 -> 38836.342 | CG17: =SUM(CE17:CE20)*1.2 -> 38836.342 | CL17: =SUM(CJ17:CJ20)*1.2 -> 38836.342 | CQ17: =SUM(CO17:CO20)*1.2 -> 38836.342 | CV17: =SUM(CT17:CT20)*1.2 -> 38836.342 | DA17: =SUM(CY17:CY20)*1.2 -> 38836.342
A18: КОЕК універсал | B18: 19420118 | C18: НВПФ "Казі-2" | D18: Активная ЭЭ | F18: =H18/G18 -> 5.799529 | G18: 5291 | H18: =1.2*25571.09 -> 30685.308 | K18: =M18/L18 -> 5.7929482 | L18: 7766 | M18: =1.2*37490.03 -> 44988.036 | P18: =R18/Q18 -> 5.7364085 | Q18: 8020 | R18: =1.2*38338.33 -> 46005.996 | U18: =W18/V18 -> 5.9058732 | V18: 10679 | W18: =1.2*52557.35 -> 63068.82 | Y18: =SUM(W17:W20)*1 -> 69766.302 | Z18: =AB18/AA18 -> 5.6497683 | AA18: 13249 | AB18: =1.2*62378.15 -> 74853.78 | AD18: =SUM(AB17:AB20)*1 -> 81386.696 | AE18: =AG18/AF18 -> 5.4696957 | AF18: 15144 | AG18: =1.2*69027.56 -> 82833.072 | AI18: =SUM(AG17:AG20)*1 -> 89422.482 | AJ18: =AL18/AK18 -> 5.8678682 | AK18: 15931 | AL18: =1.2*77900.84 -> 93481.008 | AN18: =SUM(AL17:AL20)*1 -> 100646.75 | AO18: =AQ18/AP18 -> 6.762972 | AP18: 16981 | AQ18: =1.2*95701.69 -> 114842.03 | AS18: =SUM(AQ17:AQ20)*1 -> 119658.22 | AT18: =AV18/AU18 -> 7.3032483 | AU18: 18400 | AV18: =1.2*111983.14 -> 134379.77 | AX18: =SUM(AV17:AV20)*1 -> 140613.19 | AY18: =BA18/AZ18 -> 6.1660898 | AZ18: 17081 | BA18: 105322.98 | BC18: =SUM(BA17:BA20)*1 -> 110808.9 | BD18: =BF18/BE18 -> 7.5466201 | BE18: 15358 | BF18: =1.2*96584.16 -> 115900.99 | BH18: =SUM(BF17:BF20)*1 -> 121618.18 | BI18: =BK18/BJ18 -> 7.6667398 | BJ18: 17017 | BK18: =1.2*108720.76 -> 130464.91 | BM18: =SUM(BK17:BK20)*1 -> 137135.05 | BN18: =BP18/BO18 -> 7.54662 | BO18: 14530 | BP18: =1.2*91376.99 -> 109652.39 | BR18: =SUM(BP17:BP20)*1 -> 116523.21 | BS18: =BU18/BT18 -> 7.2362638 | BT18: 14193 | BU18: =1.2*85586.91 -> 102704.29 | BW18: =SUM(BU17:BU20)*1 -> 110705.52 | BX18: =BZ18/BY18 -> 2.162003 | BY18: 14193 | BZ18: =1.2*25571.09 -> 30685.308 | CB18: =SUM(BZ17:BZ20)*1 -> 32363.618 | CC18: =CE18/CD18 -> 5.799529 | CD18: 5291 | CE18: =1.2*25571.09 -> 30685.308 | CG18: =SUM(CE17:CE20)*1 -> 32363.618 | CH18: =CJ18/CI18 -> 5.799529 | CI18: 5291 | CJ18: =1.2*25571.09 -> 30685.308 | CL18: =SUM(CJ17:CJ20)*1 -> 32363.618 | CM18: =CO18/CN18 -> 5.799529 | CN18: 5291 | CO18: =1.2*25571.09 -> 30685.308 | CQ18: =SUM(CO17:CO20)*1 -> 32363.618 | CR18: =CT18/CS18 -> 5.799529 | CS18: 5291 | CT18: =1.2*25571.09 -> 30685.308 | CV18: =SUM(CT17:CT20)*1 -> 32363.618 | CW18: =CY18/CX18 -> 5.799529 | CX18: 5291 | CY18: =1.2*25571.09 -> 30685.308 | DA18: =SUM(CY17:CY20)*1 -> 32363.618
B19: НДС | C19: НВПФ "Казі-2" | D19: Реактивная ЭЭ | G19: 1 | H19: =1.2*1286.88 -> 1544.256 | L19: 6670 | M19: =1.2*1776.61 -> 2131.932 | Q19: 7112 | R19: =1.2*2008.74 -> 2410.488 | V19: 1 | W19: =1.2*2516.66 -> 3019.992 | AA19: 1 | AB19: =1.2*2950.58 -> 3540.696 | AF19: 1 | AG19: =1.2*2967.75 -> 3561.3 | AK19: 1 | AL19: =1.2*2936.71 -> 3524.052 | AP19: 1 | AQ19: =1.2*3326.2 -> 3991.44 | AU19: 1 | AV19: =1.2*4238.22 -> 5085.864 | AZ19: 1 | BA19: 4517.72 | BE19: 1 | BF19: =1.2*3837.93 -> 4605.516 | BJ19: 1 | BK19: =1.2*4691.8 -> 5630.16 | BO19: 1 | BP19: =1.2*4829.17 -> 5795.004 | BT19: 1 | BU19: =1.2*4874.65 -> 5849.58 | BY19: 1 | BZ19: 1283.88 | CD19: 1 | CE19: 1283.88 | CI19: 1 | CJ19: 1283.88 | CN19: 1 | CO19: 1283.88 | CS19: 1 | CT19: 1283.88 | CX19: 1 | CY19: 1283.88
C20: НВПФ "Казі-2" | D20: ХВ | F20: =H20/G20 -> 35.857273 | G20: 11 | H20: 394.43 | K20: =M20/L20 -> 35.86 | L20: 24 | M20: 860.64 | P20: =R20/Q20 -> 35.860606 | Q20: 33 | R20: 1183.4 | U20: =W20/V20 -> 35.859063 | V20: 32 | W20: 1147.49 | Z20: =AB20/AA20 -> 35.86 | AA20: 27 | AB20: 968.22 | AE20: =AG20/AF20 -> 35.861071 | AF20: 28 | AG20: 1004.11 | AJ20: =AL20/AK20 -> 35.860968 | AK20: 31 | AL20: 1111.69 | AO20: =AQ20/AP20 -> 35.858696 | AP20: 23 | AQ20: 824.75 | AT20: =AV20/AU20 -> 35.86125 | AU20: 32 | AV20: 1147.56 | AY20: =BA20/AZ20 -> 35.859259 | AZ20: 27 | BA20: 968.2 | BD20: =BF20/BE20 -> 35.860323 | BE20: 31 | BF20: 1111.67 | BI20: =BK20/BJ20 -> 35.861379 | BJ20: 29 | BK20: 1039.98 | BN20: =BP20/BO20 -> 35.860667 | BO20: 30 | BP20: 1075.82 | BS20: =BU20/BT20 -> 35.860833 | BT20: 60 | BU20: 2151.65 | BX20: =BZ20/BY20 -> 35.857273 | BY20: 11 | BZ20: 394.43 | CC20: =CE20/CD20 -> 35.857273 | CD20: 11 | CE20: 394.43 | CH20: =CJ20/CI20 -> 35.857273 | CI20: 11 | CJ20: 394.43 | CM20: =CO20/CN20 -> 35.857273 | CN20: 11 | CO20: 394.43 | CR20: =CT20/CS20 -> 35.857273 | CS20: 11 | CT20: 394.43 | CW20: =CY20/CX20 -> 35.857273 | CX20: 11 | CY20: 394.43
A21: М5 | B21: г.Киев, ул. Я.Колоса,2А | C21: ТОВ "Еко-Грінко" | D21: Вывоз ТБО | W21: 1990 | Y21: =SUM(W21:W24)*1.1 -> 98311.932 | AB21: 1769 | AD21: =SUM(AB21:AB24)*1.1 -> 82767.282 | AG21: 1548 | AI21: =AI22*1.1 -> 141098.17 | AL21: 1990 | AN21: =AN22*1.2 -> 57402.214 | AQ21: 1769 | AS21: =SUM(AQ21:AQ24)*1.2 -> 242190.38 | AX21: =SUM(AV21:AV24)*1.1 -> 170273.43 | BC21: =SUM(BA21:BA24)*1.1 -> 152385.61 | BH21: =SUM(BF21:BF24)*1.1 -> 144901.7 | BM21: =SUM(BK21:BK24)*1.1 -> 135790.03 | BR21: =SUM(BP21:BP24)*1.1 -> 122838.33 | BW21: =SUM(BU21:BU24)*1.1 -> 129876.05 | CB21: =SUM(BZ21:BZ24)*1.1 -> 78943.396 | CG21: =SUM(CE21:CE24)*1.1 -> 78943.396 | CL21: =SUM(CJ21:CJ24)*1.1 -> 78943.396 | CQ21: =SUM(CO21:CO24)*1.1 -> 78943.396 | CV21: =SUM(CT21:CT24)*1.1 -> 78943.396 | DA21: =SUM(CY21:CY24)*1.1 -> 78943.396
B22: 41916045 | C22: ТОВ "КИЇВСЬКI ЕНЕРГЕТИЧНI ПОСЛУГИ" | D22: Активная ЭЭ | F22: =H22/G22 -> 5.3077196 | G22: 13395 | H22: 71096.904 | I22: 49372.85 | K22: =M22/L22 -> 5.3685478 | L22: 14950 | M22: 80259.79 | N22: 80 259,79 | P22: =R22/Q22 -> 4.9663925 | Q22: 13452 | R22: 66807.912 | S22: 66807.912 | U22: =W22/V22 -> 5.207724 | V22: 16345 | W22: 85120.248 | X22: 85120.248 | Y22: =SUM(W21:W24)*1 -> 89374.484 | Z22: =AB22/AA22 -> 4.5706785 | AA22: 15555 | AB22: 71096.904 | AC22: 72843.312 | AD22: =SUM(AB21:AB24)*1 -> 75242.984 | AE22: =AG22/AF22 -> 4.8199439 | AF22: 17766 | AG22: 85631.124 | AH22: =38338.59+87714.65 -> 126053.24 | AI22: =SUM(AG23:AG24)+AH22+AG21*1 -> 128271.06 | AJ22: =AL22/AK22 -> 4.9792194 | AK22: 8517 | AL22: 42408.012 | AM22: 44466.708 | AN22: =SUM(AL23:AL24)+AM22+AL21*1 -> 47835.178 | AO22: =AQ22/AP22 -> 5.9466962 | AP22: 33010 | AQ22: 196300.44 | AR22: 221372.05 | AS22: =SUM(AQ21:AQ24)*1 -> 201825.32 | AT22: =AV22/AU22 -> 6.6107534 | AU22: 22988 | AV22: 151968 | AW22: 49372.85 | AX22: =SUM(AV21:AV24)*1 -> 154794.03 | AY22: =BA22/AZ22 -> 6.3494522 | AZ22: 21303 | BA22: 135262.38 | BB22: 112718.65 | BC22: =SUM(BA21:BA24)*1 -> 138532.37 | BD22: =BF22/BE22 -> 6.3628441 | BE22: 20210 | BF22: 128593.08 | BG22: 112718.65 | BH22: =SUM(BF21:BF24)*1 -> 131728.82 | BI22: =BK22/BJ22 -> 6.7715879 | BJ22: 18131 | BK22: 122775.66 | BL22: 101802.85 | BM22: =SUM(BK21:BK24)*1 -> 123445.48 | BN22: =BP22/BO22 -> 6.3746277 | BO22: 17413 | BP22: 111001.39 | BQ22: 49372.85 | BR22: =SUM(BP21:BP24)*1 -> 111671.21 | BS22: =BU22/BT22 -> 6.0268797 | BT22: 19110 | BU22: 115173.67 | BV22: 112 625,82 | BW22: =SUM(BU21:BU24)*1 -> 118069.13 | BX22: =BZ22/BY22 -> 5.3077196 | BY22: 13395 | BZ22: 71096.904 | CA22: 161 248,54 | CB22: =SUM(BZ21:BZ24)*1 -> 71766.724 | CC22: =CE22/CD22 -> 5.3077196 | CD22: 13395 | CE22: 71096.904 | CF22: 49372.85 | CG22: =SUM(CE21:CE24)*1 -> 71766.724 | CH22: =CJ22/CI22 -> 5.3077196 | CI22: 13395 | CJ22: 71096.904 | CK22: 49372.85 | CL22: =SUM(CJ21:CJ24)*1 -> 71766.724 | CM22: =CO22/CN22 -> 5.3077196 | CN22: 13395 | CO22: 71096.904 | CP22: 49372.85 | CQ22: =SUM(CO21:CO24)*1 -> 71766.724 | CR22: =CT22/CS22 -> 5.3077196 | CS22: 13395 | CT22: 71096.904 | CU22: 49372.85 | CV22: =SUM(CT21:CT24)*1 -> 71766.724 | CW22: =CY22/CX22 -> 5.3077196 | CX22: 13395 | CY22: 71096.904 | CZ22: 49372.85 | DA22: =SUM(CY21:CY24)*1 -> 71766.724
B23: 41946011 | C23: «ДТЕК КИЇВСЬКІ ЕЛЕКТРОМЕРЕЖІ» | D23: Реактивная ЭЭ | H23: 1 373,92 | M23: 1352.6 | R23: 1 322,12 | W23: 1594.416 | AB23: 1707.26 | AG23: 1 819,58 | AL23: 708.65 | AQ23: 3086.06 | AV23: 2156.208 | BA23: 2600.17 | BF23: 2465.92 | BK23: 2 240,89 | BP23: 2 033,00 | BT23: 1 | BU23: 2225.64 | BZ23: 1 373,92 | CE23: 1 373,92 | CJ23: 1 373,92 | CO23: 1 373,92 | CT23: 1 373,92 | CY23: 1 373,92
C24: ФОП Ковальова Л.В. НАЛІЧНІ | D24: ХВ | F24: =H24/G24 -> 31.724138 | G24: 29 | H24: 920 | K24: =M24/L24 -> 30.446364 | L24: 22 | M24: 669.82 | P24: =R24/Q24 -> 30.446364 | Q24: 22 | R24: 669.82 | U24: =W24/V24 -> 30.446364 | V24: 22 | W24: 669.82 | Z24: =AB24/AA24 -> 30.446364 | AA24: 22 | AB24: 669.82 | AE24: =AG24/AF24 -> 30.446364 | AF24: 22 | AG24: 669.82 | AJ24: =AL24/AK24 -> 18.103243 | AK24: 37 | AL24: 669.82 | AO24: =AQ24/AP24 -> 30.446364 | AP24: 22 | AQ24: 669.82 | AT24: =AV24/AU24 -> 30.446364 | AU24: 22 | AV24: 669.82 | AY24: =BA24/AZ24 -> 30.446364 | AZ24: 22 | BA24: 669.82 | BD24: =BF24/BE24 -> 30.446364 | BE24: 22 | BF24: 669.82 | BI24: =BK24/BJ24 -> 30.446364 | BJ24: 22 | BK24: 669.82 | BN24: =BP24/BO24 -> 30.446364 | BO24: 22 | BP24: 669.82 | BS24: =BU24/BT24 -> 30.446364 | BT24: 22 | BU24: 669.82 | BX24: =BZ24/BY24 -> 30.446364 | BY24: 22 | BZ24: 669.82 | CC24: =CE24/CD24 -> 30.446364 | CD24: 22 | CE24: 669.82 | CH24: =CJ24/CI24 -> 30.446364 | CI24: 22 | CJ24: 669.82 | CM24: =CO24/CN24 -> 30.446364 | CN24: 22 | CO24: 669.82 | CR24: =CT24/CS24 -> 30.446364 | CS24: 22 | CT24: 669.82 | CW24: =CY24/CX24 -> 30.446364 | CX24: 22 | CY24: 669.82
A25: М6 | B25: г.Киев, ул. Сикорского,1А | C25: ТОВ "Еко-Грінко" | D25: Вывоз ТБО | W25: 5085 | Y25: =SUM(W25:W30)*1.1 -> 259503.07 | AB25: 5306 | AD25: =SUM(AB25:AB30)*1.1 -> 245493.75 | AG25: 5085 | AI25: =AI26*1.1 -> 373563.25 | AL25: 4643 | AN25: =AN26*1.2 -> 288508.89 | AQ25: 4422 | AS25: =SUM(AQ25:AQ30)*1.2 -> 402263.06 | AX25: =SUM(AV25:AV30)*1.1 -> 374248.29 | BC25: =SUM(BA25:BA30)*1.1 -> 348933.92 | BH25: =SUM(BF25:BF30)*1.1 -> 318419.32 | BM25: =SUM(BK25:BK30)*1.1 -> 348625.39 | BR25: =SUM(BP25:BP30)*1.1 -> 331844.84 | BW25: =SUM(BU25:BU30)*1.1 -> 365511.68 | CB25: =SUM(BZ25:BZ30)*1.1 -> 172379.6 | CG25: =SUM(CE25:CE30)*1.1 -> 172379.6 | CL25: =SUM(CJ25:CJ30)*1.1 -> 172379.6 | CQ25: =SUM(CO25:CO30)*1.1 -> 172379.6 | CV25: =SUM(CT25:CT30)*1.1 -> 172379.6 | DA25: =SUM(CY25:CY30)*1.1 -> 172379.6
B26: 32912720 | C26: ТОВ "Ковальська -Житлосервіс" | D26: Экспл. расходы | G26: 696.6 | H26: 7280.87 | L26: 696.6 | M26: 7280.87 | N26: 2940 | Q26: 696.6 | R26: 7280.87 | V26: 696.6 | W26: 7280.87 | Y26: =SUM(W25:W30)*1 -> 235911.88 | AA26: 696.6 | AB26: 7280.87 | AD26: =SUM(AB25:AB30)*1 -> 223176.14 | AF26: 696.6 | AG26: 7280.87 | AI26: =SUM(AG29:AG30)+AH28+AG27+AG26+AG25*1 -> 339602.95 | AK26: 696.6 | AL26: 7280.87 | AN26: =SUM(AL29:AL30)+AM28+AL27+AL26+AL25*1 -> 240424.08 | AP26: 696.6 | AQ26: 7280.87 | AS26: =SUM(AQ25:AQ30)*1 -> 335219.22 | AU26: 696.6 | AV26: 7 789,39 | AX26: =SUM(AV25:AV30)*1 -> 340225.72 | AZ26: 696.6 | BA26: 7 789,39 | BC26: =SUM(BA25:BA30)*1 -> 317212.66 | BE26: 696.6 | BF26: 7789.39 | BH26: =SUM(BF25:BF30)*1 -> 289472.11 | BJ26: 696.6 | BK26: 7789.39 | BM26: =SUM(BK25:BK30)*1 -> 316932.17 | BO26: 696.6 | BP26: 7789.39 | BR26: =SUM(BP25:BP30)*1 -> 301677.13 | BT26: 696.6 | BU26: 7789.39 | BW26: =SUM(BU25:BU30)*1 -> 332283.35 | BY26: 696.6 | BZ26: 7280.87 | CB26: =SUM(BZ25:BZ30)*1 -> 156708.73 | CD26: 696.6 | CE26: 7280.87 | CG26: =SUM(CE25:CE30)*1 -> 156708.73 | CI26: 696.6 | CJ26: 7280.87 | CL26: =SUM(CJ25:CJ30)*1 -> 156708.73 | CN26: 696.6 | CO26: 7280.87 | CQ26: =SUM(CO25:CO30)*1 -> 156708.73 | CS26: 696.6 | CT26: 7280.87 | CV26: =SUM(CT25:CT30)*1 -> 156708.73 | CX26: 696.6 | CY26: 7280.87 | DA26: =SUM(CY25:CY30)*1 -> 156708.73
B27: 32912720 | C27: ТОВ "Ковальська -Житлосервіс" | D27: Экспл. расходы | G27: 465.4 | H27: 4864.36 | L27: 465.4 | M27: 4864.36 | Q27: 465.4 | R27: 4864.36 | V27: 465.4 | W27: 4864.36 | AA27: 465.4 | AB27: 4864.36 | AF27: 465.4 | AG27: 4864.36 | AK27: 465.4 | AL27: 4864.36 | AP27: 465.4 | AQ27: 4864.36 | AU27: 465.4 | AV27: 5 204,10 | AZ27: 465.4 | BA27: 5 204,10 | BE27: 465.4 | BF27: 5204.1 | BJ27: 465.4 | BK27: 5204.1 | BO27: 465.4 | BP27: 5 204,10 | BT27: 465.4 | BU27: 5 204,10 | BY27: 465.4 | BZ27: 4864.36 | CD27: 465.4 | CE27: 4864.36 | CI27: 465.4 | CJ27: 4864.36 | CN27: 465.4 | CO27: 4864.36 | CS27: 465.4 | CT27: 4864.36 | CX27: 465.4 | CY27: 4864.36
B28: 41916045 | C28: ТОВ "КИЇВСЬКI ЕНЕРГЕТИЧНI ПОСЛУГИ" | D28: Активная ЭЭ | F28: =H28/G28 -> 5.3077195 | G28: 26880 | H28: 142671.5 | I28: 99077.44 | K28: =M28/L28 -> 5.3685477 | L28: 35276 | M28: =132566.62+56814.27 -> 189380.89 | N28: 189380.89 | P28: =R28/Q28 -> 4.966392 | Q28: 33553 | R28: 166637.35 | S28: 166637.35 | U28: =W28/V28 -> 5.2077239 | V28: 41331 | W28: 215240.44 | X28: 215240.44 | Z28: =AB28/AA28 -> 4.6829521 | AA28: 42840 | AB28: 200617.67 | AC28: 200617.67 | AE28: =AG28/AF28 -> 4.8199441 | AF28: 43525 | AG28: 209788.07 | AH28: =73911.77+31676.47+139680.1+75212.38 -> 320480.72 | AJ28: =AL28/AK28 -> 4.9792201 | AK28: 42360 | AL28: 210919.76 | AM28: 221158.85 | AO28: =AQ28/AP28 -> 5.946696 | AP28: 52776 | AQ28: 313842.83 | AR28: 353927.04 | AT28: =AV28/AU28 -> 6.6107622 | AU28: 50640 | AV28: 334769 | AW28: 99077.44 | AY28: =BA28/AZ28 -> 6.349452 | AZ28: 49132 | BA28: 311961.28 | BB28: 259967.73 | BD28: =BF28/BE28 -> 6.3628442 | BE28: 42815 | BF28: 272425.18 | BG28: 259967.73 | BI28: =BK28/BJ28 -> 6.771588 | BJ28: 44605 | BK28: 302046.68 | BL28: 215669.93 | BN28: =BP28/BO28 -> 6.374628 | BO28: 45060 | BP28: 287240.74 | BQ28: 99077.44 | BS28: =BU28/BT28 -> 6.0268801 | BT28: 53040 | BU28: 319665.72 | BV28: 291 444,30 | BX28: =BZ28/BY28 -> 5.3077195 | BY28: 26880 | BZ28: 142671.5 | CA28: 345590.5 | CC28: =CE28/CD28 -> 5.3077195 | CD28: 26880 | CE28: 142671.5 | CF28: 99077.44 | CH28: =CJ28/CI28 -> 5.3077195 | CI28: 26880 | CJ28: 142671.5 | CK28: 99077.44 | CM28: =CO28/CN28 -> 5.3077195 | CN28: 26880 | CO28: 142671.5 | CP28: 99077.44 | CR28: =CT28/CS28 -> 5.3077195 | CS28: 26880 | CT28: 142671.5 | CU28: 99077.44 | CW28: =CY28/CX28 -> 5.3077195 | CX28: 26880 | CY28: 142671.5 | CZ28: 99077.44
B29: 41946011 | C29: «ДТЕК КИЇВСЬКІ ЕЛЕКТРОМЕРЕЖІ» | D29: Реактивная ЭЭ | H29: 1 208,50 | M29: 1608.624 | R29: 1 481,46 | W29: 1705.212 | AB29: 2015.24 | AG29: 2 055,08 | AL29: 2 183,15 | AQ29: 2431.16 | AV29: 2940.72 | BA29: 3359.38 | BF29: 2161.44 | BK29: 2 950,96 | BP29: 2 275,88 | BT29: 1 | BU29: 2431.86 | BZ29: 1 208,50 | CE29: 1 208,50 | CJ29: 1 208,50 | CO29: 1 208,50 | CT29: 1 208,50 | CY29: 1 208,50
B30: 2839404073 | C30: ФОП Пластун В.В. | D30: ХВ | F30: =H30/G30 -> 32.446667 | G30: 57 | H30: 1849.46 | K30: =M30/L30 -> 33.254545 | L30: 55 | M30: 1829 | P30: =R30/Q30 -> 32.343667 | Q30: 60 | R30: 1940.62 | U30: =W30/V30 -> 33.384615 | V30: 52 | W30: 1736 | Z30: =AB30/AA30 -> 33.247312 | AA30: 93 | AB30: 3092 | AE30: =AG30/AF30 -> 1892 | AF30: 1 | AG30: 1892 | AJ30: =AL30/AK30 -> 33.472973 | AK30: 74 | AL30: 2477 | AO30: =AQ30/AP30 -> 32.135135 | AP30: 74 | AQ30: 2378 | AT30: =AV30/AU30 -> 35.43662 | AU30: 71 | AV30: 2516 | AY30: =BA30/AZ30 -> 1892 | AZ30: 1 | BA30: 1892 | BD30: =BF30/BE30 -> 1892 | BE30: 1 | BF30: 1892 | BI30: =BK30/BJ30 -> 35.037037 | BJ30: 54 | BK30: 1892 | BN30: =BP30/BO30 -> 48.518248 | BO30: 137 | BP30: 6647 | BS30: =BU30/BT30 -> 31.951733 | BT30: 75 | BU30: 2396.38 | BX30: =BZ30/BY30 -> 1892 | BY30: 1 | BZ30: 1892 | CC30: =CE30/CD30 -> 1892 | CD30: 1 | CE30: 1892 | CH30: =CJ30/CI30 -> 1892 | CI30: 1 | CJ30: 1892 | CM30: =CO30/CN30 -> 1892 | CN30: 1 | CO30: 1892 | CR30: =CT30/CS30 -> 1892 | CS30: 1 | CT30: 1892 | CW30: =CY30/CX30 -> 1892 | CX30: 1 | CY30: 1892
A31: М7 | B31: г.Киев, ул. Коновальца,44Б | C31: ТОВ "Еко-Грінко" | D31: Вывоз ТБО | W31: 1769 | Y31: =SUM(W31:W37)*1.1 -> 128568.93 | AB31: 1327 | AD31: =SUM(AB31:AB37)*1.1 -> 145940.86 | AG31: 1769 | AI31: =AI32*1.1 -> 167258.3 | AL31: 1106 | AN31: =AN32*1.2 -> 243742.02 | AQ31: 1990 | AS31: =SUM(AQ31:AQ37)*1.2 -> 249696.68 | AX31: =SUM(AV31:AV37)*1.1 -> 335982.68 | BC31: =SUM(BA31:BA37)*1.1 -> 249573.1 | BH31: =SUM(BF31:BF37)*1.1 -> 240436.79 | BM31: =SUM(BK31:BK37)*1.1 -> 250447.47 | BR31: =SUM(BP31:BP37)*1.1 -> 228835.35 | BW31: =SUM(BU31:BU37)*1.1 -> 181035.97 | CB31: =SUM(BZ31:BZ37)*1.1 -> 106588.73 | CG31: =SUM(CE31:CE37)*1.1 -> 106588.73 | CL31: =SUM(CJ31:CJ37)*1.1 -> 106588.73 | CQ31: =SUM(CO31:CO37)*1.1 -> 106588.73 | CV31: =SUM(CT31:CT37)*1.1 -> 106588.73 | DA31: =SUM(CY31:CY37)*1.1 -> 106588.73
C32: ТОВ "ОК "Комфорт" | D32: Послуга із забезпечення технічної | V32: 1 | W32: 9274.13 | Y32: =SUM(W31:W37)*1 -> 116880.84 | AA32: 1 | AB32: 9974.36 | AD32: =SUM(AB31:AB37)*1 -> 132673.51 | AG32: 11967.32 | AI32: =SUM(AG31:AG37)*1 -> 152053 | AL32: 16764.1 | AN32: =SUM(AL31:AL37)*1 -> 203118.35 | AQ32: 18754.75 | AS32: =SUM(AQ31:AQ37)*1 -> 208080.56 | AV32: 26166.5 | AX32: =SUM(AV31:AV37)*1 -> 305438.8 | BA32: 18885.72 | BC32: =SUM(BA31:BA37)*1 -> 226884.64 | BF32: 17254.72 | BH32: =SUM(BF31:BF37)*1 -> 218578.9 | BK32: =17675.04+94.188+286.76 -> 18055.988 | BM32: =SUM(BK31:BK37)*1 -> 227679.52 | BP32: 17 384,99 | BR32: =SUM(BP31:BP37)*1 -> 208032.14 | BU32: 15130.36 | BW32: =SUM(BU31:BU37)*1 -> 164578.16 | CB32: =SUM(BZ31:BZ37)*1 -> 96898.848 | CG32: =SUM(CE31:CE37)*1 -> 96898.848 | CL32: =SUM(CJ31:CJ37)*1 -> 96898.848 | CQ32: =SUM(CO31:CO37)*1 -> 96898.848 | CV32: =SUM(CT31:CT37)*1 -> 96898.848 | DA32: =SUM(CY31:CY37)*1 -> 96898.848
B33: 39397773 | C33: ТОВ "ОК "Комфорт" | D33: Экспл. расходы | G33: 1 | H33: =17607.25+1534.43 -> 19141.68 | L33: 1 | M33: =17607.25+1534.43 -> 19141.68 | Q33: 1 | R33: =17607.25+1534.43 -> 19141.68 | V33: 1 | W33: =17607.25+1534.43 -> 19141.68 | AA33: 1 | AB33: =17607.25+1534.43 -> 19141.68 | AF33: 1 | AG33: 17607.25 | AK33: 1 | AL33: 17607.25 | AP33: 1 | AQ33: 17607.25 | AU33: 1 | AV33: =17607.25 -> 17607.25 | AZ33: 1 | BA33: =17607.25+1534.43 -> 19141.68 | BE33: 1 | BF33: 28776.97 | BJ33: 1 | BK33: 28776.97 | BO33: 1 | BP33: 28776.97 | BT33: 1 | BU33: 28 776,97 | BY33: 1 | BZ33: =17607.25+1534.43 -> 19141.68 | CD33: 1 | CE33: =17607.25+1534.43 -> 19141.68 | CI33: 1 | CJ33: =17607.25+1534.43 -> 19141.68 | CN33: 1 | CO33: =17607.25+1534.43 -> 19141.68 | CS33: 1 | CT33: =17607.25+1534.43 -> 19141.68 | CX33: 1 | CY33: =17607.25+1534.43 -> 19141.68
C34: ТОВ "ОК "Комфорт" | D34: Реактивная ЭЭ | G34: 1 | H34: =1.2*639.79 -> 767.748 | L34: 1 | M34: =1.2*639.79 -> 767.748 | Q34: 5880 | R34: =1.2*712.83 -> 855.396 | V34: 1 | W34: =1.2*943.49 -> 1132.188 | AA34: 1 | AB34: =1.2*1096.02 -> 1315.224 | AF34: 1 | AG34: =1.2*1281.77 -> 1538.124 | AK34: 1 | AL34: =1.2*1566.38 -> 1879.656 | AP34: 1 | AQ34: =1.2*1547.34 -> 1856.808 | AU34: 1 | AV34: =1.2*2205.75 -> 2646.9 | AZ34: 1 | BA34: =1.2*1978.19 -> 2373.828 | BE34: 1 | BF34: =1.2*1724.34 -> 2069.208 | BJ34: 1 | BK34: =1.2*1652.95 -> 1983.54 | BO34: 1 | BP34: =1.2*1098.73 -> 1318.476 | BT34: 1 | BU34: 1546.49 | BY34: 1 | BZ34: =1.2*639.79 -> 767.748 | CD34: 1 | CE34: =1.2*639.79 -> 767.748 | CI34: 1 | CJ34: =1.2*639.79 -> 767.748 | CN34: 1 | CO34: =1.2*639.79 -> 767.748 | CS34: 1 | CT34: =1.2*639.79 -> 767.748 | CX34: 1 | CY34: =1.2*639.79 -> 767.748
A35: ЯСНО "КИЇВСЬКІ ЕНЕРГЕТИЧНІ ПОСЛУГИ" | C35: ТОВ "ОК "Комфорт" | D35: Активная ЭЭ | F35: =H35/G35 -> 5.0962317 | G35: 14970 | H35: =63575.49*1.2 -> 76290.588 | K35: =M35/L35 -> 5.875313 | L35: 14790 | M35: 86895.88 | P35: =R35/Q35 -> 5.5478991 | Q35: 18390 | R35: =9352.84+77227.52*1.2 -> 102025.86 | U35: =W35/V35 -> 5.089392 | V35: 18000 | W35: =1.2*76340.88 -> 91609.056 | Z35: =AB35/AA35 -> 4.7757601 | AA35: 20610 | AB35: =82023.68*1.2 -> 98428.416 | AE35: =AG35/AF35 -> 4.7047078 | AF35: 25110 | AG35: =98446.01*1.2 -> 118135.21 | AJ35: =AL35/AK35 -> 4.955496 | AK35: 33450 | AL35: =1.2*138134.45 -> 165761.34 | AO35: =AQ35/AP35 -> 5.867004 | AP35: 31650 | AQ35: =154742.23*1.2 -> 185690.68 | AT35: =AV35/AU35 -> 6.5161799 | AU35: 39750 | AV35: =1.2*215848.46 -> 259018.15 | AY35: =BA35/AZ35 -> 6.3494521 | AZ35: 29370 | BA35: =1.2*155402.84 -> 186483.41 | BD35: =BF35/BE35 -> 6.6 | BE35: 25830 | BF35: =1.2*142065 -> 170478 | BI35: =BK35/BJ35 -> 6.8055598 | BJ35: 25680 | BK35: =1.2*145638.98 -> 174766.78 | BN35: =BP35/BO35 -> 6.7185121 | BO35: 25680 | BP35: =1.2*143776.16 -> 172531.39 | BS35: =BU35/BT35 -> 5.9659799 | BT35: 25050 | BU35: =124539.83*1.2 -> 149447.8 | BX35: =BZ35/BY35 -> 5.0962317 | BY35: 14970 | BZ35: =63575.49*1.2 -> 76290.588 | CC35: =CE35/CD35 -> 5.0962317 | CD35: 14970 | CE35: =63575.49*1.2 -> 76290.588 | CH35: =CJ35/CI35 -> 5.0962317 | CI35: 14970 | CJ35: =63575.49*1.2 -> 76290.588 | CM35: =CO35/CN35 -> 5.0962317 | CN35: 14970 | CO35: =63575.49*1.2 -> 76290.588 | CR35: =CT35/CS35 -> 5.0962317 | CS35: 14970 | CT35: =63575.49*1.2 -> 76290.588 | CW35: =CY35/CX35 -> 5.0962317 | CX35: 14970 | CY35: =63575.49*1.2 -> 76290.588
C36: ТОВ "ОК "Комфорт" | D36: Тепловая энергия | G36: 0.41 | L36: 0.940 | M36: 2682.91 | Q36: 0.89 | R36: 2540.18 | V36: 0.78 | W36: 2226.25 | AA36: 0 | AB36: 1484.16 | AF36: 0 | AK36: 0 | AP36: 0 | AU36: 0 | AZ36: 0 | BE36: 0.41 | BK36: 3154.34 | BO36: 0.94 | BP36: 4706.47 | BT36: 0.41 | BU36: 5 006,88 | BY36: 0.41 | CD36: 0.41 | CI36: 0.41 | CN36: 0.41 | CS36: 0.41 | CX36: 0.41
C37: ТОВ "ОК "Комфорт" | D37: ХВ | G37: 22 | H37: =1.2*(309.81+272.55) -> 698.832 | L37: 23 | M37: 768.72 | Q37: 25 | R37: 835.56 | U37: =W37/V37 -> 33.422333 | V37: 30 | W37: 1002.67 | Z37: =AB37/AA37 -> 33.422333 | AA37: 30 | AB37: 1002.67 | AF37: 31 | AG37: 1036.09 | AK37: 33 | AL37: 1102.94 | AP37: 28 | AQ37: 935.83 | AU37: 30 | AV37: 1002.67 | AZ37: 30 | BA37: 1002.67 | BE37: 26 | BF37: 868.98 | BI37: =BK37/BJ37 -> 30.384 | BJ37: 31 | BK37: =1.2*784.92 -> 941.904 | BO37: 23 | BP37: =1.2*(309.81+272.55) -> 698.832 | BT37: 31 | BU37: 1 036,09 | BY37: 23 | BZ37: =1.2*(309.81+272.55) -> 698.832 | CD37: 23 | CE37: =1.2*(309.81+272.55) -> 698.832 | CI37: 23 | CJ37: =1.2*(309.81+272.55) -> 698.832 | CN37: 23 | CO37: =1.2*(309.81+272.55) -> 698.832 | CS37: 23 | CT37: =1.2*(309.81+272.55) -> 698.832 | CX37: 23 | CY37: =1.2*(309.81+272.55) -> 698.832
A38: М8 | B38: г.Ирпень, 10-я линия,1Б | C38: ПП "Обухівміськвторресурси" | D38: Вывоз ТБО | W38: 2277 | Y38: =SUM(W38:W43)*1.1 -> 207970.84 | AB38: 2530 | AD38: =SUM(AB38:AB43)*1.1 -> 182839.66 | AG38: 4301 | AI38: =AI39*1.1 -> 30482.903 | AL38: 4048 | AN38: =AN39*1.2 -> 213801.05 | AS38: =SUM(AQ38:AQ43)*1.2 -> 279236.06 | AX38: =SUM(AV38:AV43)*1.1 -> 296544.54 | BC38: =SUM(BA38:BA43)*1.1 -> 120848.06 | BH38: =SUM(BF38:BF43)*1.1 -> 237060.42 | BM38: =SUM(BK38:BK43)*1.1 -> 236698.6 | BR38: =SUM(BP38:BP43)*1.1 -> 279330.39 | BW38: =SUM(BU38:BU43)*1.1 -> 269576.14 | CB38: =SUM(BZ38:BZ43)*1.1 -> 117959.87 | CG38: =SUM(CE38:CE43)*1.1 -> 117959.87 | CL38: =SUM(CJ38:CJ43)*1.1 -> 117959.87 | CQ38: =SUM(CO38:CO43)*1.1 -> 117959.87 | CV38: =SUM(CT38:CT43)*1.1 -> 117959.87 | DA38: =SUM(CY38:CY43)*1.1 -> 117959.87
B39: 40397750 | C39: ТОВ "ТЦ "Вайт Хауз" | D39: Экспл. расходы | H39: 17000 | L39: 1 | M39: 17000 | Q39: 1 | R39: 19000 | V39: 1 | W39: 19000 | Y39: =SUM(W38:W43)*1 -> 189064.4 | AA39: 1 | AB39: 19000 | AD39: =SUM(AB38:AB42)*1 -> 164925.2 | AF39: 1 | AG39: 19000 | AI39: =SUM(AG42:AG43)+AH41+AG40+AG39+AG38*1 -> 27711.73 | AK39: 1 | AL39: 19000 | AN39: =SUM(AL43)+AM41+AL40+AL39+AL38+AM42*1 -> 178167.54 | AP39: 1 | AQ39: 19000 | AS39: =SUM(AQ38:AQ43)*1 -> 232696.72 | AU39: 1 | AV39: 19000 | AX39: =SUM(AV38:AV43)*1 -> 269585.95 | AZ39: 1 | BA39: 19000 | BC39: =SUM(BA38:BA43)*1 -> 109861.87 | BE39: 1 | BF39: 19000 | BH39: =SUM(BF38:BF43)*1 -> 215509.48 | BJ39: 1 | BK39: 19000 | BM39: =SUM(BK38:BK43)*1 -> 215180.54 | BO39: 1 | BP39: 19000 | BR39: =SUM(BP38:BP43)*1 -> 253936.72 | BT39: 1 | BU39: 21 000 | BW39: =SUM(BU38:BU43)*1 -> 245069.22 | BY39: 1 | BZ39: 21000 | CB39: =SUM(BZ38:BZ43)*1 -> 107236.24 | CD39: 1 | CE39: 21000 | CG39: =SUM(CE38:CE43)*1 -> 107236.24 | CI39: 1 | CJ39: 21000 | CL39: =SUM(CJ38:CJ43)*1 -> 107236.24 | CN39: 1 | CO39: 21000 | CQ39: =SUM(CO38:CO43)*1 -> 107236.24 | CS39: 1 | CT39: 21000 | CV39: =SUM(CT38:CT43)*1 -> 107236.24 | CX39: 1 | CY39: 21000 | DA39: =SUM(CY38:CY43)*1 -> 107236.24
B40: 40397750 | C40: ТОВ "ТЦ "Вайт Хауз" | D40: ХВ | G40: 2 | H40: 67.43 | L40: 4 | M40: 134.86 | V40: 1 | W40: 33.72 | AA40: 1 | AB40: 303.44 | AF40: 7 | AG40: 236.01 | AI40: =AG38+AG39+AG40+AG41+AG42+AG43 -> 170318.36 | AK40: 5 | AL40: 185.38 | AN40: =AL38+AL39+AL40+AM42+AM41 -> 178167.54 | AP40: 6 | AQ40: 219.09 | AU40: 6 | AV40: 219.64 | AZ40: 7 | BA40: 253.44 | BE40: 7 | BF40: 253.44 | BJ40: 7 | BK40: 253.44 | BO40: 7 | BP40: 253.44 | BT40: 8 | BU40: 287.24
B41: 44878589 | C41: ТОВ ТОЛК | D41: Активная ЭЭ | F41: =H41/G41 -> 5.834472 | G41: 14641 | H41: 85422.504 | I41: 59321.18 | K41: =M41/L41 -> 0 | L41: 21940 | M41: 0 | P41: =R41/Q41 -> 5.463492 | Q41: 21598 | R41: 118000.5 | S41: 118000.5 | U41: =W41/V41 -> 5.6633998 | V41: 28737 | W41: 162749.12 | X41: 118000.5 | Z41: =AB41/AA41 -> 5.2304759 | AA41: 26894 | AB41: 140668.42 | AC41: 0 | AE41: =AG41/AF41 -> 5.3864638 | AF41: 26475 | AG41: 142606.63 | AH41: 0 | AJ41: =AL41/AK41 -> 5.651892 | AK41: 26882 | AL41: 151934.16 | AM41: 151934.16 | AO41: =AQ41/AP41 -> 6.821652 | AP41: 30774 | AQ41: 209929.52 | AR41: 230791.34 | AT41: =AV41/AU41 -> 7.5147962 | AU41: 32646 | AV41: =1.2*204440.03 -> 245328.04 | AW41: 59321.18 | AY41: =BA41/AZ41 -> 2.9535476 | AZ41: 28922 | BA41: 85422.504 | BB41: 59321.18 | BD41: =BF41/BE41 -> 7.2173641 | BE41: 26581 | BF41: 191844.76 | BG41: 0 | BI41: =BK41/BJ41 -> 7.5240961 | BJ41: 25728 | BK41: =1.2*161316.62 -> 193579.94 | BL41: 151877.1 | BN41: =BP41/BO41 -> 7.0861201 | BO41: 32311 | BP41: =1.2*190799.69 -> 228959.63 | BQ41: 0 | BS41: =BU41/BT41 -> 7.0129999 | BT41: 34788 | BU41: 243968.24 | BV41: =157195.68+86772.56 -> 243968.24 | BX41: =BZ41/BY41 -> 4.2711252 | BY41: 20000 | BZ41: 85422.504 | CA41: 105341.6 | CC41: =CE41/CD41 -> 5.834472 | CD41: 14641 | CE41: 85422.504 | CF41: 0 | CH41: =CJ41/CI41 -> 5.834472 | CI41: 14641 | CJ41: 85422.504 | CK41: 0 | CM41: =CO41/CN41 -> 5.834472 | CN41: 14641 | CO41: 85422.504 | CP41: 0 | CR41: =CT41/CS41 -> 5.834472 | CS41: 14641 | CT41: 85422.504 | CU41: 0 | CW41: =CY41/CX41 -> 5.834472 | CX41: 14641 | CY41: 85422.504 | CZ41: 0
...

Sheet ОПЛАТИ 2024-2025-2026 
B1: НАЗВАНИЕ ОБЪЕКТА | C1: АДРЕС ОБЪЕКТА | D1: ЮРИДИЧЕСКОЕ (ФИЗИЧЕСКОЕ) ЛИЦО | E1: НАИМЕНОВАНИЕ | F1: Столбец1 | G1: Тариф | H1: Показатели | I1: Сумма | J1: Авансы | K1: грудень 2022 | L1: Тариф | M1: Показатели | N1: Сумма | O1: Авансы | P1: січень 2023 | Q1: Тариф | R1: Показатели | S1: Сумма | T1: Авансы | U1: лютий 2023 | V1: Тариф | W1: Показатели | X1: Сумма | Y1: Авансы | Z1: березень 2023 | AA1: Тариф | AB1: Показатели | AC1: Сумма | AD1: Авансы | AE1: квітень 2023 | AF1: Тариф | AG1: Показатели | AH1: Сумма | AI1: Авансы | AJ1: травень 2023 | AK1: Тариф | AL1: Показатели | AM1: Сумма | AN1: Авансы | AO1: червень 2023 | AP1: Тариф | AQ1: Показатели | AR1: Сумма | AS1: Авансы | AT1: Липень 2023 | AU1: Тариф | AV1: Показатели | AW1: Сумма | AX1: Авансы | AY1: Серпень 2023 | AZ1: Тариф | BA1: Показатели | BB1: Сумма | BC1: Авансы | BD1: Вересень 2023 | BE1: Тариф | BF1: Показатели | BG1: Сумма | BH1: Авансы | BI1: Жовтень 2023 | BJ1: Тариф | BK1: Показатели | BL1: Сумма | BM1: Авансы | BN1: Листопад 2023 | BO1: Тариф | BP1: Показатели | BQ1: Сумма | BR1: Авансы | BS1: Грудень 2023 | BT1: Тариф | BU1: Показатели | BV1: Сумма | BW1: Авансы | BX1: Січень 2024 | BY1: Тариф | BZ1: Показатели | CA1: Сумма | CB1: Авансы | CC1: Лютий 2024 | CD1: Тариф | CE1: Показатели | CF1: Сумма | CG1: Авансы | CH1: Березень 2024 | CI1: Тариф | CJ1: Показатели | CK1: Сумма | CL1: Авансы | CM1: Квітень 2024 | CN1: Тариф | CO1: Показатели | CP1: Сумма | CQ1: Авансы | CR1: Травень 2024 | CS1: Тариф | CT1: Показатели | CU1: Сумма | CV1: Авансы | CW1: червень 2024 | CX1: Тариф | CY1: Показатели | CZ1: Сумма | DA1: Авансы | DB1: Липень 2024 | DC1: Тариф | DD1: Показатели | DE1: Сумма | DF1: Авансы | DG1: Серпень 2024 | DH1: Тариф | DI1: Показатели | DJ1: Сумма | DK1: Авансы | DL1: Вересен 2024 | DM1: Тариф | DN1: Показатели | DO1: Сумма | DP1: Авансы | DQ1: Жовтень 2024 | DR1: Тариф | DS1: Показатели | DT1: Сумма | DU1: Авансы | DV1: Листопад 2024 | DW1: Тариф | DX1: Показатели | DY1: Сумма | DZ1: Авансы | EA1: Грудень 2024 | EB1: Тариф | EC1: Показатели | ED1: Сумма | EE1: Авансы | EF1: Січень 2025 | EG1: Тариф | EH1: Показатели | EI1: Сумма | EJ1: Авансы | EK1: Лютий 2025 | EL1: Тариф | EM1: Показатели | EN1: Сумма | EO1: Авансы | EP1: Березень 2025 | EQ1: Тариф | ER1: Показатели | ES1: Сумма | ET1: Авансы | EU1: Квітень 2025 | EV1: Тариф | EW1: Показатели | EX1: Сумма | EY1: Авансы | EZ1: Травень 2025 | FA1: Тариф | FB1: Показатели | FC1: Сумма | FD1: Авансы | FE1: червень 2025 | FF1: Тариф | FG1: Показатели | FH1: Сумма | FI1: Авансы | FJ1: Липень 2025 | FK1: Тариф | FL1: Показатели | FM1: Сумма | FN1: Авансы | FO1: Серпень 2025 | FP1: Тариф | FQ1: Показатели | FR1: Сумма | FS1: Авансы | FT1: Вересен 2025 | FU1: Тариф | FV1: Показатели | FW1: Сумма | FX1: Авансы | FY1: Жовтень 2025 | FZ1: Тариф | GA1: Показатели | GB1: Сумма | GC1: Авансы | GD1: Листопад 2025 | GE1: Тариф | GF1: Показатели | GG1: Сумма | GH1: Авансы | GI1: Грудень 2025 | GJ1: Тариф | GK1: Показатели | GL1: Сумма | GM1: Авансы | GN1: Січень 2026 | GO1: Тариф | GP1: Показатели | GQ1: Сумма | GR1: Авансы | GS1: Лютий 2026 | GT1: Тариф | GU1: Показатели | GV1: Сумма | GW1: Авансы | GX1: Березень 2026 | GY1: Тариф | GZ1: Показатели | HA1: Сумма | HB1: Авансы | HC1: Квітень 2026 | HD1: Тариф | HE1: Показатели | HF1: Сумма | HG1: Авансы | HH1: Травень 2026 | HI1: Тариф | HJ1: Показатели | HK1: Сумма | HL1: Авансы | HM1: червень 2026 | HN1: Тариф | HO1: Показатели | HP1: Сумма | HQ1: Авансы | HR1: Липень 2026 | HS1: Тариф | HT1: Показатели | HU1: Сумма | HV1: Авансы | HW1: Серпень 2026 | HX1: Тариф | HY1: Показатели | HZ1: Сумма | IA1: Авансы | IB1: Вересен 2026 | IC1: Тариф | ID1: Показатели | IE1: Сумма | IF1: Авансы | IG1: Жовтень 2026 | IH1: Тариф | II1: Показатели | IJ1: Сумма | IK1: Авансы | IL1: Листопад 2026 | IM1: Тариф | IN1: Показатели | IO1: Сумма | IP1: Авансы | IQ1: Грудень 2026
B2: РЦ | C2: Білогородка, Аграрна 1
C3: 44878589 | D3: ТОВ ТОЛК | E3: Активная ЭЭ | EW3: 67210 | EX3: 559858.76 | FB3: 88730 | FC3: 794292.86 | FG3: 89720 | FH3: 855837.29 | FI3: 620 620,56 | FL3: 75890 | FM3: 735882.26 | FN3: 546986.88 | FS3: 312287.23 | GT3: =GV3/GU3 -> 11.233164 | GU3: =18310+950 -> 19260 | GV3: 216350.74 | HE3: 67210 | HF3: 559858.76 | HJ3: 88730 | HK3: 794292.86 | HO3: 89720 | HP3: 855837.29 | HQ3: 620 620,56 | HT3: 75890 | HU3: 735882.26 | HV3: 546986.88 | IA3: 312287.23
C4: 23243188 | D4: «ДТЕК КИЇВСЬКІ РЕГІОНАЛЬНІ ЕЛЕКТРОМЕРЕЖІ» | E4: Реактивная ЭЭ | FN4: 16 569,92 | FW4: 10688.9 | GV4: 22972.92 | GW4: 22972.92 | HV4: 16 569,92 | IE4: 10688.9
C5: 40635553 | D5: ТОВ "Сервіс-Енергія ЛТД" | E5: КОМЕРЦІЙНИЙ ОБЛІК | FE5: 812 214,78 | FG5: 1 | FH5: 1 440,00 | FL5: 1 | FM5: 1 440,00 | FQ5: 1 | FR5: 1 440,00 | FV5: 1 | FW5: 1 440,00 | GV5: 1440 | HM5: 812 214,78 | HO5: 1 | HP5: 1 440,00 | HT5: 1 | HU5: 1 440,00 | HY5: 1 | HZ5: 1 440,00 | ID5: 1 | IE5: 1 440,00
B8: М1/1 | C8: г.Житомир, пр. Мира, 15 | D8: ТОВ ГРІН БІН Україна | E8: Вывоз ТБО | X8: 2 913,33 | Z8: =SUM(X8:X12)*1.1 -> 266598.77 | AA8: 330000 | AC8: 100 | AE8: =SUM(AC8:AC12)*1.1 -> 254435.93 | AH8: =3277.5+600 -> 3877.5 | AJ8: =AJ9*1.1 -> 304938.28 | AM8: 100 | AO8: =AO9*1.2 -> 244056.49 | AR8: 100 | AT8: =SUM(AR8:AR12)*1.3 -> 417523.31 | AW8: 100 | AY8: =SUM(AW8:AW12)*1 -> 339604.38 | BB8: 100 | BD8: =SUM(BB8:BB12)*1.11 -> 341852.35 | BG8: 100 | BI8: =SUM(BG8:BG12)*1.1 -> 326765.93 | BL8: 100 | BN8: =SUM(BL8:BL12)*1.1 -> 373177.56 | BQ8: 100 | BS8: =SUM(BQ8:BQ12)*1.1 -> 407182.36 | BV8: 100 | BX8: =SUM(BV8:BV12)*1.1 -> 385830.64 | CA8: 100 | CC8: =SUM(CA8:CA12)*1.1 -> 332482.38 | CF8: 100 | CH8: =SUM(CF8:CF12)*1.1 -> 334293.7 | CK8: 100 | CM8: =SUM(CK8:CK12)*1.1 -> 310806.02 | CP8: 100 | CR8: =SUM(CP8:CP12)*1.1 -> 374522.28 | CU8: 100 | CW8: =SUM(CU8:CU12)*1.1 -> 465603.58 | CZ8: 100 | DB8: =SUM(CZ8:CZ12)*1.1 -> 524540.47 | DE8: 100 | DG8: =SUM(DE8:DE12)*1.1 -> 492256.18 | DJ8: 100 | DL8: =SUM(DJ8:DJ12)*1.1 -> 463958.34 | DO8: 100 | DQ8: =SUM(DO8:DO12)*1.1 -> 509103.65 | DT8: 100 | DV8: =SUM(DT8:DT12)*1.1 -> 506792.51 | DY8: 100 | EA8: =SUM(DY8:DY12)*1.1 -> 550649.62 | ED8: 100 | EF8: =SUM(ED8:ED12)*1.1 -> 548888.81 | EI8: 100 | EK8: =SUM(EI8:EI12)*1.1 -> 589577.05 | EN8: 100 | EP8: =SUM(EN8:EN12)*1.1 -> 396906.58 | ES8: 100 | EU8: =SUM(ES8:ES12)*1.1 -> 532550.17 | EX8: 100 | EZ8: =SUM(EX8:EX12)*1.1 -> 503620.55 | FC8: 100 | FE8: =SUM(FC8:FC12)*1.1 -> 453684.69 | FH8: 100 | FJ8: =SUM(FH8:FH12)*1.1 -> 522971.69 | FM8: 100 | FO8: =SUM(FM8:FM12)*1.1 -> 566179.69 | FR8: 100 | FT8: =SUM(FR8:FR12)*1.1 -> 478467.72 | FW8: 100 | FY8: =SUM(FW8:FW12)*1.1 -> 595643.42 | GB8: 100 | GD8: =SUM(GB8:GB12)*1.1 -> 588465.13 | GG8: 100 | GI8: =SUM(GG8:GG12)*1.1 -> 676933.99 | GL8: 100 | GN8: =SUM(GL8:GL12)*1.1 -> 548888.81 | GQ8: 100 | GS8: =SUM(GQ8:GQ12)*1.1 -> 752381.14 | GV8: 100 | GX8: =SUM(GV8:GV12)*1.1 -> 655159.43 | HA8: 100 | HC8: =SUM(HA8:HA12)*1.1 -> 532550.17 | HF8: 100 | HH8: =SUM(HF8:HF12)*1.1 -> 503620.55 | HK8: 100 | HM8: =SUM(HK8:HK12)*1.1 -> 453684.69 | HP8: 100 | HR8: =SUM(HP8:HP12)*1.1 -> 522971.69 | HU8: 100 | HW8: =SUM(HU8:HU12)*1.1 -> 566179.69 | HZ8: 100 | IB8: =SUM(HZ8:HZ12)*1.1 -> 478467.72 | IE8: 100 | IG8: =SUM(IE8:IE12)*1.1 -> 595643.42 | IJ8: 100 | IL8: =SUM(IJ8:IJ12)*1.1 -> 272793.49 | IO8: 100 | IQ8: =SUM(IO8:IO12)*1.1 -> 266185.5
